Workbook
Name DA: Solver!$D$64:$X$84
Name DB: Solver!$D$148:$X$168
Name dx: Inputs!$B$9
Name dx_2: Inputs!$B$23
Name dx_3: Inputs!$B$22
Name err_2: Error!$D$133:$X$153
Name err_3: Error!$D$189:$X$209
Name errA: Error!$D$49:$X$69
Name errB: Error!$D$77:$X$97
Name ia: Inputs!$B$13
Name ib: Inputs!$B$14
Name ja: Inputs!$B$15
Name jb: Inputs!$B$16
Name L: Inputs!$B$5
Name N: Inputs!$B$6
Name N_2: Inputs!$B$21
Name N_3: Inputs!$B$20
Name rho: Inputs!$B$8
Name U0: Inputs!$B$7
Name uA: Solver!$D$8:$X$28
Name uB: Solver!$D$92:$X$112
Name vA: Solver!$D$36:$X$56
Name vB: Solver!$D$120:$X$140

Sheet Inputs
A1: F01 · Conservation of mass
A2: Every physical quantity below is a named cell. The formulas on the other tabs use the names.
A4: Name | B4: Value | C4: Unit | D4: Meaning
A5: L | B5: 1 | C5: m | D5: side of the square domain
A6: N | B6: 21 | C6: - | D6: cells per direction on the main grid (5 to 21)
A7: U0 | B7: 1 | C7: m/s | D7: velocity scale
A8: rho | B8: 1 | C8: kg/m3 | D8: density, constant
A9: dx | B9: =L/N -> 0.047619048 | C9: m | D9: cell size, computed from L and N
A11: Control volume, given as node indices on the main grid
A12: The divergence is not defined on the boundary nodes, so the box must satisfy 2 <= ia < ib <= N-1 and 2 <= ja < jb <= N-1.
A13: ia | B13: 3 | C13: - | D13: west face, node index
A14: ib | B14: 13 | C14: - | D14: east face, node index
A15: ja | B15: 5 | C15: - | D15: south face, node index
A16: jb | B16: 17 | C16: - | D16: north face, node index
A17: check | B17: =IF(OR(ia<2,ib>N-1,ja<2,jb>N-1,ia>=ib,ja>=jb),"box is outside the interior","ok") -> ok | D17: the box must lie inside the interior nodes
A19: Two coarser grids, used for the grid study on the Error tab
A20: N_3 | B20: 6 | C20: - | D20: coarsest grid, cells per direction
A21: N_2 | B21: 11 | C21: - | D21: middle grid, cells per direction
A22: dx_3 | B22: =L/N_3 -> 0.16666667 | C22: m | D22: cell size of the N_3 grid
A23: dx_2 | B23: =L/N_2 -> 0.090909091 | C23: m | D23: cell size of the N_2 grid
A25: Colour code
C26: input cell: type a value here
C27: boundary node: the central difference needs a neighbour on both sides, so no value is computed
C28: no fill: computed by a formula

Sheet Solver
A1: F01 · Solver
A2: Field A is the Taylor-Green field, equation (12). Field B is the test field, equation (14).
A4: u of field A [m/s]
A5: i | D5: 1 | E5: 2 | F5: 3 | G5: 4 | H5: 5 | I5: 6 | J5: 7 | K5: 8 | L5: 9 | M5: 10 | N5: 11 | O5: 12 | P5: 13 | Q5: 14 | R5: 15 | S5: 16 | T5: 17 | U5: 18 | V5: 19 | W5: 20 | X5: 21
A6: x [m] | D6: =IF(1<=N,(1-0.5)*dx,"") -> 0.023809524 | E6: =IF(2<=N,(2-0.5)*dx,"") -> 0.071428571 | F6: =IF(3<=N,(3-0.5)*dx,"") -> 0.11904762 | G6: =IF(4<=N,(4-0.5)*dx,"") -> 0.16666667 | H6: =IF(5<=N,(5-0.5)*dx,"") -> 0.21428571 | I6: =IF(6<=N,(6-0.5)*dx,"") -> 0.26190476 | J6: =IF(7<=N,(7-0.5)*dx,"") -> 0.30952381 | K6: =IF(8<=N,(8-0.5)*dx,"") -> 0.35714286 | L6: =IF(9<=N,(9-0.5)*dx,"") -> 0.4047619 | M6: =IF(10<=N,(10-0.5)*dx,"") -> 0.45238095 | N6: =IF(11<=N,(11-0.5)*dx,"") -> 0.5 | O6: =IF(12<=N,(12-0.5)*dx,"") -> 0.54761905 | P6: =IF(13<=N,(13-0.5)*dx,"") -> 0.5952381 | Q6: =IF(14<=N,(14-0.5)*dx,"") -> 0.64285714 | R6: =IF(15<=N,(15-0.5)*dx,"") -> 0.69047619 | S6: =IF(16<=N,(16-0.5)*dx,"") -> 0.73809524 | T6: =IF(17<=N,(17-0.5)*dx,"") -> 0.78571429 | U6: =IF(18<=N,(18-0.5)*dx,"") -> 0.83333333 | V6: =IF(19<=N,(19-0.5)*dx,"") -> 0.88095238 | W6: =IF(20<=N,(20-0.5)*dx,"") -> 0.92857143 | X6: =IF(21<=N,(21-0.5)*dx,"") -> 0.97619048
A7: j | B7: y [m]
A8: 1 | B8: =IF(1<=N,(1-0.5)*dx,"") -> 0.023809524 | D8: =IF(COUNT($B8,D$6)<2,"",U0*SIN(PI()*D$6/L)*COS(PI()*$B8/L)) -> 0.074521133 | E8: =IF(COUNT($B8,E$6)<2,"",U0*SIN(PI()*E$6/L)*COS(PI()*$B8/L)) -> 0.22189872 | F8: =IF(COUNT($B8,F$6)<2,"",U0*SIN(PI()*F$6/L)*COS(PI()*$B8/L)) -> 0.36431946 | G8: =IF(COUNT($B8,G$6)<2,"",U0*SIN(PI()*G$6/L)*COS(PI()*$B8/L)) -> 0.4986019 | H8: =IF(COUNT($B8,H$6)<2,"",U0*SIN(PI()*H$6/L)*COS(PI()*$B8/L)) -> 0.6217464 | I8: =IF(COUNT($B8,I$6)<2,"",U0*SIN(PI()*I$6/L)*COS(PI()*$B8/L)) -> 0.73100211 | J8: =IF(COUNT($B8,J$6)<2,"",U0*SIN(PI()*J$6/L)*COS(PI()*$B8/L)) -> 0.82392844 | K8: =IF(COUNT($B8,K$6)<2,"",U0*SIN(PI()*K$6/L)*COS(PI()*$B8/L)) -> 0.89844958 | ... X8: =IF(COUNT($B8,X$6)<2,"",U0*SIN(PI()*X$6/L)*COS(PI()*$B8/L)) -> 0.074521133
A9: 2 | B9: =IF(2<=N,(2-0.5)*dx,"") -> 0.071428571 | D9: =IF(COUNT($B9,D$6)<2,"",U0*SIN(PI()*D$6/L)*COS(PI()*$B9/L)) -> 0.072856454 | E9: =IF(COUNT($B9,E$6)<2,"",U0*SIN(PI()*E$6/L)*COS(PI()*$B9/L)) -> 0.21694187 | F9: =IF(COUNT($B9,F$6)<2,"",U0*SIN(PI()*F$6/L)*COS(PI()*$B9/L)) -> 0.35618116 | G9: =IF(COUNT($B9,G$6)<2,"",U0*SIN(PI()*G$6/L)*COS(PI()*$B9/L)) -> 0.48746396 | H9: =IF(COUNT($B9,H$6)<2,"",U0*SIN(PI()*H$6/L)*COS(PI()*$B9/L)) -> 0.60785761 | I9: =IF(COUNT($B9,I$6)<2,"",U0*SIN(PI()*I$6/L)*COS(PI()*$B9/L)) -> 0.71467273 | J9: =IF(COUNT($B9,J$6)<2,"",U0*SIN(PI()*J$6/L)*COS(PI()*$B9/L)) -> 0.80552324 | K9: =IF(COUNT($B9,K$6)<2,"",U0*SIN(PI()*K$6/L)*COS(PI()*$B9/L)) -> 0.8783797 | ... X9: =IF(COUNT($B9,X$6)<2,"",U0*SIN(PI()*X$6/L)*COS(PI()*$B9/L)) -> 0.072856454
A10: 3 | B10: =IF(3<=N,(3-0.5)*dx,"") -> 0.11904762 | D10: =IF(COUNT($B10,D$6)<2,"",U0*SIN(PI()*D$6/L)*COS(PI()*$B10/L)) -> 0.069564282 | E10: =IF(COUNT($B10,E$6)<2,"",U0*SIN(PI()*E$6/L)*COS(PI()*$B10/L)) -> 0.2071389 | F10: =IF(COUNT($B10,F$6)<2,"",U0*SIN(PI()*F$6/L)*COS(PI()*$B10/L)) -> 0.34008637 | G10: =IF(COUNT($B10,G$6)<2,"",U0*SIN(PI()*G$6/L)*COS(PI()*$B10/L)) -> 0.46543687 | H10: =IF(COUNT($B10,H$6)<2,"",U0*SIN(PI()*H$6/L)*COS(PI()*$B10/L)) -> 0.58039029 | I10: =IF(COUNT($B10,I$6)<2,"",U0*SIN(PI()*I$6/L)*COS(PI()*$B10/L)) -> 0.68237874 | J10: =IF(COUNT($B10,J$6)<2,"",U0*SIN(PI()*J$6/L)*COS(PI()*$B10/L)) -> 0.76912399 | K10: =IF(COUNT($B10,K$6)<2,"",U0*SIN(PI()*K$6/L)*COS(PI()*$B10/L)) -> 0.83868827 | ... X10: =IF(COUNT($B10,X$6)<2,"",U0*SIN(PI()*X$6/L)*COS(PI()*$B10/L)) -> 0.069564282
A11: 4 | B11: =IF(4<=N,(4-0.5)*dx,"") -> 0.16666667 | D11: =IF(COUNT($B11,D$6)<2,"",U0*SIN(PI()*D$6/L)*COS(PI()*$B11/L)) -> 0.064718159 | E11: =IF(COUNT($B11,E$6)<2,"",U0*SIN(PI()*E$6/L)*COS(PI()*$B11/L)) -> 0.19270878 | F11: =IF(COUNT($B11,F$6)<2,"",U0*SIN(PI()*F$6/L)*COS(PI()*$B11/L)) -> 0.31639461 | G11: =IF(COUNT($B11,G$6)<2,"",U0*SIN(PI()*G$6/L)*COS(PI()*$B11/L)) -> 0.4330127 | H11: =IF(COUNT($B11,H$6)<2,"",U0*SIN(PI()*H$6/L)*COS(PI()*$B11/L)) -> 0.53995801 | I11: =IF(COUNT($B11,I$6)<2,"",U0*SIN(PI()*I$6/L)*COS(PI()*$B11/L)) -> 0.63484154 | J11: =IF(COUNT($B11,J$6)<2,"",U0*SIN(PI()*J$6/L)*COS(PI()*$B11/L)) -> 0.71554377 | K11: =IF(COUNT($B11,K$6)<2,"",U0*SIN(PI()*K$6/L)*COS(PI()*$B11/L)) -> 0.78026193 | ... X11: =IF(COUNT($B11,X$6)<2,"",U0*SIN(PI()*X$6/L)*COS(PI()*$B11/L)) -> 0.064718159
A12: 5 | B12: =IF(5<=N,(5-0.5)*dx,"") -> 0.21428571 | D12: =IF(COUNT($B12,D$6)<2,"",U0*SIN(PI()*D$6/L)*COS(PI()*$B12/L)) -> 0.05842634 | E12: =IF(COUNT($B12,E$6)<2,"",U0*SIN(PI()*E$6/L)*COS(PI()*$B12/L)) -> 0.17397387 | F12: =IF(COUNT($B12,F$6)<2,"",U0*SIN(PI()*F$6/L)*COS(PI()*$B12/L)) -> 0.28563511 | G12: =IF(COUNT($B12,G$6)<2,"",U0*SIN(PI()*G$6/L)*COS(PI()*$B12/L)) -> 0.39091574 | H12: =IF(COUNT($B12,H$6)<2,"",U0*SIN(PI()*H$6/L)*COS(PI()*$B12/L)) -> 0.48746396 | I12: =IF(COUNT($B12,I$6)<2,"",U0*SIN(PI()*I$6/L)*COS(PI()*$B12/L)) -> 0.57312303 | J12: =IF(COUNT($B12,J$6)<2,"",U0*SIN(PI()*J$6/L)*COS(PI()*$B12/L)) -> 0.64597949 | K12: =IF(COUNT($B12,K$6)<2,"",U0*SIN(PI()*K$6/L)*COS(PI()*$B12/L)) -> 0.70440583 | ... X12: =IF(COUNT($B12,X$6)<2,"",U0*SIN(PI()*X$6/L)*COS(PI()*$B12/L)) -> 0.05842634
A13: 6 | B13: =IF(6<=N,(6-0.5)*dx,"") -> 0.26190476 | D13: =IF(COUNT($B13,D$6)<2,"",U0*SIN(PI()*D$6/L)*COS(PI()*$B13/L)) -> 0.050829372 | E13: =IF(COUNT($B13,E$6)<2,"",U0*SIN(PI()*E$6/L)*COS(PI()*$B13/L)) -> 0.15135267 | F13: =IF(COUNT($B13,F$6)<2,"",U0*SIN(PI()*F$6/L)*COS(PI()*$B13/L)) -> 0.248495 | G13: =IF(COUNT($B13,G$6)<2,"",U0*SIN(PI()*G$6/L)*COS(PI()*$B13/L)) -> 0.34008637 | H13: =IF(COUNT($B13,H$6)<2,"",U0*SIN(PI()*H$6/L)*COS(PI()*$B13/L)) -> 0.42408077 | I13: =IF(COUNT($B13,I$6)<2,"",U0*SIN(PI()*I$6/L)*COS(PI()*$B13/L)) -> 0.4986019 | J13: =IF(COUNT($B13,J$6)<2,"",U0*SIN(PI()*J$6/L)*COS(PI()*$B13/L)) -> 0.56198509 | K13: =IF(COUNT($B13,K$6)<2,"",U0*SIN(PI()*K$6/L)*COS(PI()*$B13/L)) -> 0.61281446 | ... X13: =IF(COUNT($B13,X$6)<2,"",U0*SIN(PI()*X$6/L)*COS(PI()*$B13/L)) -> 0.050829372
A14: 7 | B14: =IF(7<=N,(7-0.5)*dx,"") -> 0.30952381 | D14: =IF(COUNT($B14,D$6)<2,"",U0*SIN(PI()*D$6/L)*COS(PI()*$B14/L)) -> 0.042096961 | E14: =IF(COUNT($B14,E$6)<2,"",U0*SIN(PI()*E$6/L)*COS(PI()*$B14/L)) -> 0.12535051 | F14: =IF(COUNT($B14,F$6)<2,"",U0*SIN(PI()*F$6/L)*COS(PI()*$B14/L)) -> 0.20580393 | G14: =IF(COUNT($B14,G$6)<2,"",U0*SIN(PI()*G$6/L)*COS(PI()*$B14/L)) -> 0.28166003 | H14: =IF(COUNT($B14,H$6)<2,"",U0*SIN(PI()*H$6/L)*COS(PI()*$B14/L)) -> 0.35122431 | I14: =IF(COUNT($B14,I$6)<2,"",U0*SIN(PI()*I$6/L)*COS(PI()*$B14/L)) -> 0.41294282 | J14: =IF(COUNT($B14,J$6)<2,"",U0*SIN(PI()*J$6/L)*COS(PI()*$B14/L)) -> 0.46543687 | K14: =IF(COUNT($B14,K$6)<2,"",U0*SIN(PI()*K$6/L)*COS(PI()*$B14/L)) -> 0.50753383 | ... X14: =IF(COUNT($B14,X$6)<2,"",U0*SIN(PI()*X$6/L)*COS(PI()*$B14/L)) -> 0.042096961
A15: 8 | B15: =IF(8<=N,(8-0.5)*dx,"") -> 0.35714286 | D15: =IF(COUNT($B15,D$6)<2,"",U0*SIN(PI()*D$6/L)*COS(PI()*$B15/L)) -> 0.032424172 | E15: =IF(COUNT($B15,E$6)<2,"",U0*SIN(PI()*E$6/L)*COS(PI()*$B15/L)) -> 0.096548215 | F15: =IF(COUNT($B15,F$6)<2,"",U0*SIN(PI()*F$6/L)*COS(PI()*$B15/L)) -> 0.15851553 | G15: =IF(COUNT($B15,G$6)<2,"",U0*SIN(PI()*G$6/L)*COS(PI()*$B15/L)) -> 0.21694187 | H15: =IF(COUNT($B15,H$6)<2,"",U0*SIN(PI()*H$6/L)*COS(PI()*$B15/L)) -> 0.27052209 | I15: =IF(COUNT($B15,I$6)<2,"",U0*SIN(PI()*I$6/L)*COS(PI()*$B15/L)) -> 0.31805929 | J15: =IF(COUNT($B15,J$6)<2,"",U0*SIN(PI()*J$6/L)*COS(PI()*$B15/L)) -> 0.35849157 | K15: =IF(COUNT($B15,K$6)<2,"",U0*SIN(PI()*K$6/L)*COS(PI()*$B15/L)) -> 0.39091574 | ... X15: =IF(COUNT($B15,X$6)<2,"",U0*SIN(PI()*X$6/L)*COS(PI()*$B15/L)) -> 0.032424172
A16: 9 | B16: =IF(9<=N,(9-0.5)*dx,"") -> 0.4047619 | D16: =IF(COUNT($B16,D$6)<2,"",U0*SIN(PI()*D$6/L)*COS(PI()*$B16/L)) -> 0.022027082 | E16: =IF(COUNT($B16,E$6)<2,"",U0*SIN(PI()*E$6/L)*COS(PI()*$B16/L)) -> 0.065589197 | F16: =IF(COUNT($B16,F$6)<2,"",U0*SIN(PI()*F$6/L)*COS(PI()*$B16/L)) -> 0.10768616 | G16: =IF(COUNT($B16,G$6)<2,"",U0*SIN(PI()*G$6/L)*COS(PI()*$B16/L)) -> 0.14737759 | H16: =IF(COUNT($B16,H$6)<2,"",U0*SIN(PI()*H$6/L)*COS(PI()*$B16/L)) -> 0.18377685 | I16: =IF(COUNT($B16,I$6)<2,"",U0*SIN(PI()*I$6/L)*COS(PI()*$B16/L)) -> 0.21607083 | J16: =IF(COUNT($B16,J$6)<2,"",U0*SIN(PI()*J$6/L)*COS(PI()*$B16/L)) -> 0.24353815 | K16: =IF(COUNT($B16,K$6)<2,"",U0*SIN(PI()*K$6/L)*COS(PI()*$B16/L)) -> 0.26556524 | ... X16: =IF(COUNT($B16,X$6)<2,"",U0*SIN(PI()*X$6/L)*COS(PI()*$B16/L)) -> 0.022027082
A17: 10 | B17: =IF(10<=N,(10-0.5)*dx,"") -> 0.45238095 | D17: =IF(COUNT($B17,D$6)<2,"",U0*SIN(PI()*D$6/L)*COS(PI()*$B17/L)) -> 0.011137942 | E17: =IF(COUNT($B17,E$6)<2,"",U0*SIN(PI()*E$6/L)*COS(PI()*$B17/L)) -> 0.033165024 | F17: =IF(COUNT($B17,F$6)<2,"",U0*SIN(PI()*F$6/L)*COS(PI()*$B17/L)) -> 0.054451254 | G17: =IF(COUNT($B17,G$6)<2,"",U0*SIN(PI()*G$6/L)*COS(PI()*$B17/L)) -> 0.074521133 | H17: =IF(COUNT($B17,H$6)<2,"",U0*SIN(PI()*H$6/L)*COS(PI()*$B17/L)) -> 0.092926333 | I17: =IF(COUNT($B17,I$6)<2,"",U0*SIN(PI()*I$6/L)*COS(PI()*$B17/L)) -> 0.10925571 | J17: =IF(COUNT($B17,J$6)<2,"",U0*SIN(PI()*J$6/L)*COS(PI()*$B17/L)) -> 0.1231445 | K17: =IF(COUNT($B17,K$6)<2,"",U0*SIN(PI()*K$6/L)*COS(PI()*$B17/L)) -> 0.13428244 | ... X17: =IF(COUNT($B17,X$6)<2,"",U0*SIN(PI()*X$6/L)*COS(PI()*$B17/L)) -> 0.011137942
A18: 11 | B18: =IF(11<=N,(11-0.5)*dx,"") -> 0.5 | D18: =IF(COUNT($B18,D$6)<2,"",U0*SIN(PI()*D$6/L)*COS(PI()*$B18/L)) -> 4.5777729e-18 | E18: =IF(COUNT($B18,E$6)<2,"",U0*SIN(PI()*E$6/L)*COS(PI()*$B18/L)) -> 1.3631059e-17 | F18: =IF(COUNT($B18,F$6)<2,"",U0*SIN(PI()*F$6/L)*COS(PI()*$B18/L)) -> 2.237985e-17 | G18: =IF(COUNT($B18,G$6)<2,"",U0*SIN(PI()*G$6/L)*COS(PI()*$B18/L)) -> 3.0628711e-17 | H18: =IF(COUNT($B18,H$6)<2,"",U0*SIN(PI()*H$6/L)*COS(PI()*$B18/L)) -> 3.8193378e-17 | I18: =IF(COUNT($B18,I$6)<2,"",U0*SIN(PI()*I$6/L)*COS(PI()*$B18/L)) -> 4.4904868e-17 | J18: =IF(COUNT($B18,J$6)<2,"",U0*SIN(PI()*J$6/L)*COS(PI()*$B18/L)) -> 5.0613258e-17 | K18: =IF(COUNT($B18,K$6)<2,"",U0*SIN(PI()*K$6/L)*COS(PI()*$B18/L)) -> 5.5191031e-17 | ... X18: =IF(COUNT($B18,X$6)<2,"",U0*SIN(PI()*X$6/L)*COS(PI()*$B18/L)) -> 4.5777729e-18
A19: 12 | B19: =IF(12<=N,(12-0.5)*dx,"") -> 0.54761905 | D19: =IF(COUNT($B19,D$6)<2,"",U0*SIN(PI()*D$6/L)*COS(PI()*$B19/L)) -> -0.011137942 | E19: =IF(COUNT($B19,E$6)<2,"",U0*SIN(PI()*E$6/L)*COS(PI()*$B19/L)) -> -0.033165024 | F19: =IF(COUNT($B19,F$6)<2,"",U0*SIN(PI()*F$6/L)*COS(PI()*$B19/L)) -> -0.054451254 | G19: =IF(COUNT($B19,G$6)<2,"",U0*SIN(PI()*G$6/L)*COS(PI()*$B19/L)) -> -0.074521133 | H19: =IF(COUNT($B19,H$6)<2,"",U0*SIN(PI()*H$6/L)*COS(PI()*$B19/L)) -> -0.092926333 | I19: =IF(COUNT($B19,I$6)<2,"",U0*SIN(PI()*I$6/L)*COS(PI()*$B19/L)) -> -0.10925571 | J19: =IF(COUNT($B19,J$6)<2,"",U0*SIN(PI()*J$6/L)*COS(PI()*$B19/L)) -> -0.1231445 | K19: =IF(COUNT($B19,K$6)<2,"",U0*SIN(PI()*K$6/L)*COS(PI()*$B19/L)) -> -0.13428244 | ... X19: =IF(COUNT($B19,X$6)<2,"",U0*SIN(PI()*X$6/L)*COS(PI()*$B19/L)) -> -0.011137942
A20: 13 | B20: =IF(13<=N,(13-0.5)*dx,"") -> 0.5952381 | D20: =IF(COUNT($B20,D$6)<2,"",U0*SIN(PI()*D$6/L)*COS(PI()*$B20/L)) -> -0.022027082 | E20: =IF(COUNT($B20,E$6)<2,"",U0*SIN(PI()*E$6/L)*COS(PI()*$B20/L)) -> -0.065589197 | F20: =IF(COUNT($B20,F$6)<2,"",U0*SIN(PI()*F$6/L)*COS(PI()*$B20/L)) -> -0.10768616 | G20: =IF(COUNT($B20,G$6)<2,"",U0*SIN(PI()*G$6/L)*COS(PI()*$B20/L)) -> -0.14737759 | H20: =IF(COUNT($B20,H$6)<2,"",U0*SIN(PI()*H$6/L)*COS(PI()*$B20/L)) -> -0.18377685 | I20: =IF(COUNT($B20,I$6)<2,"",U0*SIN(PI()*I$6/L)*COS(PI()*$B20/L)) -> -0.21607083 | J20: =IF(COUNT($B20,J$6)<2,"",U0*SIN(PI()*J$6/L)*COS(PI()*$B20/L)) -> -0.24353815 | K20: =IF(COUNT($B20,K$6)<2,"",U0*SIN(PI()*K$6/L)*COS(PI()*$B20/L)) -> -0.26556524 | ... X20: =IF(COUNT($B20,X$6)<2,"",U0*SIN(PI()*X$6/L)*COS(PI()*$B20/L)) -> -0.022027082
A21: 14 | B21: =IF(14<=N,(14-0.5)*dx,"") -> 0.64285714 | D21: =IF(COUNT($B21,D$6)<2,"",U0*SIN(PI()*D$6/L)*COS(PI()*$B21/L)) -> -0.032424172 | E21: =IF(COUNT($B21,E$6)<2,"",U0*SIN(PI()*E$6/L)*COS(PI()*$B21/L)) -> -0.096548215 | F21: =IF(COUNT($B21,F$6)<2,"",U0*SIN(PI()*F$6/L)*COS(PI()*$B21/L)) -> -0.15851553 | G21: =IF(COUNT($B21,G$6)<2,"",U0*SIN(PI()*G$6/L)*COS(PI()*$B21/L)) -> -0.21694187 | H21: =IF(COUNT($B21,H$6)<2,"",U0*SIN(PI()*H$6/L)*COS(PI()*$B21/L)) -> -0.27052209 | I21: =IF(COUNT($B21,I$6)<2,"",U0*SIN(PI()*I$6/L)*COS(PI()*$B21/L)) -> -0.31805929 | J21: =IF(COUNT($B21,J$6)<2,"",U0*SIN(PI()*J$6/L)*COS(PI()*$B21/L)) -> -0.35849157 | K21: =IF(COUNT($B21,K$6)<2,"",U0*SIN(PI()*K$6/L)*COS(PI()*$B21/L)) -> -0.39091574 | ... X21: =IF(COUNT($B21,X$6)<2,"",U0*SIN(PI()*X$6/L)*COS(PI()*$B21/L)) -> -0.032424172
A22: 15 | B22: =IF(15<=N,(15-0.5)*dx,"") -> 0.69047619 | D22: =IF(COUNT($B22,D$6)<2,"",U0*SIN(PI()*D$6/L)*COS(PI()*$B22/L)) -> -0.042096961 | E22: =IF(COUNT($B22,E$6)<2,"",U0*SIN(PI()*E$6/L)*COS(PI()*$B22/L)) -> -0.12535051 | F22: =IF(COUNT($B22,F$6)<2,"",U0*SIN(PI()*F$6/L)*COS(PI()*$B22/L)) -> -0.20580393 | G22: =IF(COUNT($B22,G$6)<2,"",U0*SIN(PI()*G$6/L)*COS(PI()*$B22/L)) -> -0.28166003 | H22: =IF(COUNT($B22,H$6)<2,"",U0*SIN(PI()*H$6/L)*COS(PI()*$B22/L)) -> -0.35122431 | I22: =IF(COUNT($B22,I$6)<2,"",U0*SIN(PI()*I$6/L)*COS(PI()*$B22/L)) -> -0.41294282 | J22: =IF(COUNT($B22,J$6)<2,"",U0*SIN(PI()*J$6/L)*COS(PI()*$B22/L)) -> -0.46543687 | K22: =IF(COUNT($B22,K$6)<2,"",U0*SIN(PI()*K$6/L)*COS(PI()*$B22/L)) -> -0.50753383 | ... X22: =IF(COUNT($B22,X$6)<2,"",U0*SIN(PI()*X$6/L)*COS(PI()*$B22/L)) -> -0.042096961
A23: 16 | B23: =IF(16<=N,(16-0.5)*dx,"") -> 0.73809524 | D23: =IF(COUNT($B23,D$6)<2,"",U0*SIN(PI()*D$6/L)*COS(PI()*$B23/L)) -> -0.050829372 | E23: =IF(COUNT($B23,E$6)<2,"",U0*SIN(PI()*E$6/L)*COS(PI()*$B23/L)) -> -0.15135267 | F23: =IF(COUNT($B23,F$6)<2,"",U0*SIN(PI()*F$6/L)*COS(PI()*$B23/L)) -> -0.248495 | G23: =IF(COUNT($B23,G$6)<2,"",U0*SIN(PI()*G$6/L)*COS(PI()*$B23/L)) -> -0.34008637 | H23: =IF(COUNT($B23,H$6)<2,"",U0*SIN(PI()*H$6/L)*COS(PI()*$B23/L)) -> -0.42408077 | I23: =IF(COUNT($B23,I$6)<2,"",U0*SIN(PI()*I$6/L)*COS(PI()*$B23/L)) -> -0.4986019 | J23: =IF(COUNT($B23,J$6)<2,"",U0*SIN(PI()*J$6/L)*COS(PI()*$B23/L)) -> -0.56198509 | K23: =IF(COUNT($B23,K$6)<2,"",U0*SIN(PI()*K$6/L)*COS(PI()*$B23/L)) -> -0.61281446 | ... X23: =IF(COUNT($B23,X$6)<2,"",U0*SIN(PI()*X$6/L)*COS(PI()*$B23/L)) -> -0.050829372
A24: 17 | B24: =IF(17<=N,(17-0.5)*dx,"") -> 0.78571429 | D24: =IF(COUNT($B24,D$6)<2,"",U0*SIN(PI()*D$6/L)*COS(PI()*$B24/L)) -> -0.05842634 | E24: =IF(COUNT($B24,E$6)<2,"",U0*SIN(PI()*E$6/L)*COS(PI()*$B24/L)) -> -0.17397387 | F24: =IF(COUNT($B24,F$6)<2,"",U0*SIN(PI()*F$6/L)*COS(PI()*$B24/L)) -> -0.28563511 | G24: =IF(COUNT($B24,G$6)<2,"",U0*SIN(PI()*G$6/L)*COS(PI()*$B24/L)) -> -0.39091574 | H24: =IF(COUNT($B24,H$6)<2,"",U0*SIN(PI()*H$6/L)*COS(PI()*$B24/L)) -> -0.48746396 | I24: =IF(COUNT($B24,I$6)<2,"",U0*SIN(PI()*I$6/L)*COS(PI()*$B24/L)) -> -0.57312303 | J24: =IF(COUNT($B24,J$6)<2,"",U0*SIN(PI()*J$6/L)*COS(PI()*$B24/L)) -> -0.64597949 | K24: =IF(COUNT($B24,K$6)<2,"",U0*SIN(PI()*K$6/L)*COS(PI()*$B24/L)) -> -0.70440583 | ... X24: =IF(COUNT($B24,X$6)<2,"",U0*SIN(PI()*X$6/L)*COS(PI()*$B24/L)) -> -0.05842634
A25: 18 | B25: =IF(18<=N,(18-0.5)*dx,"") -> 0.83333333 | D25: =IF(COUNT($B25,D$6)<2,"",U0*SIN(PI()*D$6/L)*COS(PI()*$B25/L)) -> -0.064718159 | E25: =IF(COUNT($B25,E$6)<2,"",U0*SIN(PI()*E$6/L)*COS(PI()*$B25/L)) -> -0.19270878 | F25: =IF(COUNT($B25,F$6)<2,"",U0*SIN(PI()*F$6/L)*COS(PI()*$B25/L)) -> -0.31639461 | G25: =IF(COUNT($B25,G$6)<2,"",U0*SIN(PI()*G$6/L)*COS(PI()*$B25/L)) -> -0.4330127 | H25: =IF(COUNT($B25,H$6)<2,"",U0*SIN(PI()*H$6/L)*COS(PI()*$B25/L)) -> -0.53995801 | I25: =IF(COUNT($B25,I$6)<2,"",U0*SIN(PI()*I$6/L)*COS(PI()*$B25/L)) -> -0.63484154 | J25: =IF(COUNT($B25,J$6)<2,"",U0*SIN(PI()*J$6/L)*COS(PI()*$B25/L)) -> -0.71554377 | K25: =IF(COUNT($B25,K$6)<2,"",U0*SIN(PI()*K$6/L)*COS(PI()*$B25/L)) -> -0.78026193 | ... X25: =IF(COUNT($B25,X$6)<2,"",U0*SIN(PI()*X$6/L)*COS(PI()*$B25/L)) -> -0.064718159
A26: 19 | B26: =IF(19<=N,(19-0.5)*dx,"") -> 0.88095238 | D26: =IF(COUNT($B26,D$6)<2,"",U0*SIN(PI()*D$6/L)*COS(PI()*$B26/L)) -> -0.069564282 | E26: =IF(COUNT($B26,E$6)<2,"",U0*SIN(PI()*E$6/L)*COS(PI()*$B26/L)) -> -0.2071389 | F26: =IF(COUNT($B26,F$6)<2,"",U0*SIN(PI()*F$6/L)*COS(PI()*$B26/L)) -> -0.34008637 | G26: =IF(COUNT($B26,G$6)<2,"",U0*SIN(PI()*G$6/L)*COS(PI()*$B26/L)) -> -0.46543687 | H26: =IF(COUNT($B26,H$6)<2,"",U0*SIN(PI()*H$6/L)*COS(PI()*$B26/L)) -> -0.58039029 | I26: =IF(COUNT($B26,I$6)<2,"",U0*SIN(PI()*I$6/L)*COS(PI()*$B26/L)) -> -0.68237874 | J26: =IF(COUNT($B26,J$6)<2,"",U0*SIN(PI()*J$6/L)*COS(PI()*$B26/L)) -> -0.76912399 | K26: =IF(COUNT($B26,K$6)<2,"",U0*SIN(PI()*K$6/L)*COS(PI()*$B26/L)) -> -0.83868827 | ... X26: =IF(COUNT($B26,X$6)<2,"",U0*SIN(PI()*X$6/L)*COS(PI()*$B26/L)) -> -0.069564282
A27: 20 | B27: =IF(20<=N,(20-0.5)*dx,"") -> 0.92857143 | D27: =IF(COUNT($B27,D$6)<2,"",U0*SIN(PI()*D$6/L)*COS(PI()*$B27/L)) -> -0.072856454 | E27: =IF(COUNT($B27,E$6)<2,"",U0*SIN(PI()*E$6/L)*COS(PI()*$B27/L)) -> -0.21694187 | F27: =IF(COUNT($B27,F$6)<2,"",U0*SIN(PI()*F$6/L)*COS(PI()*$B27/L)) -> -0.35618116 | G27: =IF(COUNT($B27,G$6)<2,"",U0*SIN(PI()*G$6/L)*COS(PI()*$B27/L)) -> -0.48746396 | H27: =IF(COUNT($B27,H$6)<2,"",U0*SIN(PI()*H$6/L)*COS(PI()*$B27/L)) -> -0.60785761 | I27: =IF(COUNT($B27,I$6)<2,"",U0*SIN(PI()*I$6/L)*COS(PI()*$B27/L)) -> -0.71467273 | J27: =IF(COUNT($B27,J$6)<2,"",U0*SIN(PI()*J$6/L)*COS(PI()*$B27/L)) -> -0.80552324 | K27: =IF(COUNT($B27,K$6)<2,"",U0*SIN(PI()*K$6/L)*COS(PI()*$B27/L)) -> -0.8783797 | ... X27: =IF(COUNT($B27,X$6)<2,"",U0*SIN(PI()*X$6/L)*COS(PI()*$B27/L)) -> -0.072856454
A28: 21 | B28: =IF(21<=N,(21-0.5)*dx,"") -> 0.97619048 | D28: =IF(COUNT($B28,D$6)<2,"",U0*SIN(PI()*D$6/L)*COS(PI()*$B28/L)) -> -0.074521133 | E28: =IF(COUNT($B28,E$6)<2,"",U0*SIN(PI()*E$6/L)*COS(PI()*$B28/L)) -> -0.22189872 | F28: =IF(COUNT($B28,F$6)<2,"",U0*SIN(PI()*F$6/L)*COS(PI()*$B28/L)) -> -0.36431946 | G28: =IF(COUNT($B28,G$6)<2,"",U0*SIN(PI()*G$6/L)*COS(PI()*$B28/L)) -> -0.4986019 | H28: =IF(COUNT($B28,H$6)<2,"",U0*SIN(PI()*H$6/L)*COS(PI()*$B28/L)) -> -0.6217464 | I28: =IF(COUNT($B28,I$6)<2,"",U0*SIN(PI()*I$6/L)*COS(PI()*$B28/L)) -> -0.73100211 | J28: =IF(COUNT($B28,J$6)<2,"",U0*SIN(PI()*J$6/L)*COS(PI()*$B28/L)) -> -0.82392844 | K28: =IF(COUNT($B28,K$6)<2,"",U0*SIN(PI()*K$6/L)*COS(PI()*$B28/L)) -> -0.89844958 | ... X28: =IF(COUNT($B28,X$6)<2,"",U0*SIN(PI()*X$6/L)*COS(PI()*$B28/L)) -> -0.074521133
A32: v of field A [m/s]
A33: i | D33: 1 | E33: 2 | F33: 3 | G33: 4 | H33: 5 | I33: 6 | J33: 7 | K33: 8 | L33: 9 | M33: 10 | N33: 11 | O33: 12 | P33: 13 | Q33: 14 | R33: 15 | S33: 16 | T33: 17 | U33: 18 | V33: 19 | W33: 20 | X33: 21
A34: x [m] | D34: =IF(1<=N,(1-0.5)*dx,"") -> 0.023809524 | E34: =IF(2<=N,(2-0.5)*dx,"") -> 0.071428571 | F34: =IF(3<=N,(3-0.5)*dx,"") -> 0.11904762 | G34: =IF(4<=N,(4-0.5)*dx,"") -> 0.16666667 | H34: =IF(5<=N,(5-0.5)*dx,"") -> 0.21428571 | I34: =IF(6<=N,(6-0.5)*dx,"") -> 0.26190476 | J34: =IF(7<=N,(7-0.5)*dx,"") -> 0.30952381 | K34: =IF(8<=N,(8-0.5)*dx,"") -> 0.35714286 | L34: =IF(9<=N,(9-0.5)*dx,"") -> 0.4047619 | M34: =IF(10<=N,(10-0.5)*dx,"") -> 0.45238095 | N34: =IF(11<=N,(11-0.5)*dx,"") -> 0.5 | O34: =IF(12<=N,(12-0.5)*dx,"") -> 0.54761905 | P34: =IF(13<=N,(13-0.5)*dx,"") -> 0.5952381 | Q34: =IF(14<=N,(14-0.5)*dx,"") -> 0.64285714 | R34: =IF(15<=N,(15-0.5)*dx,"") -> 0.69047619 | S34: =IF(16<=N,(16-0.5)*dx,"") -> 0.73809524 | T34: =IF(17<=N,(17-0.5)*dx,"") -> 0.78571429 | U34: =IF(18<=N,(18-0.5)*dx,"") -> 0.83333333 | V34: =IF(19<=N,(19-0.5)*dx,"") -> 0.88095238 | W34: =IF(20<=N,(20-0.5)*dx,"") -> 0.92857143 | X34: =IF(21<=N,(21-0.5)*dx,"") -> 0.97619048
A35: j | B35: y [m]
A36: 1 | B36: =IF(1<=N,(1-0.5)*dx,"") -> 0.023809524 | D36: =IF(COUNT($B36,D$34)<2,"",-U0*COS(PI()*D$34/L)*SIN(PI()*$B36/L)) -> -0.074521133 | E36: =IF(COUNT($B36,E$34)<2,"",-U0*COS(PI()*E$34/L)*SIN(PI()*$B36/L)) -> -0.072856454 | F36: =IF(COUNT($B36,F$34)<2,"",-U0*COS(PI()*F$34/L)*SIN(PI()*$B36/L)) -> -0.069564282 | G36: =IF(COUNT($B36,G$34)<2,"",-U0*COS(PI()*G$34/L)*SIN(PI()*$B36/L)) -> -0.064718159 | H36: =IF(COUNT($B36,H$34)<2,"",-U0*COS(PI()*H$34/L)*SIN(PI()*$B36/L)) -> -0.05842634 | I36: =IF(COUNT($B36,I$34)<2,"",-U0*COS(PI()*I$34/L)*SIN(PI()*$B36/L)) -> -0.050829372 | J36: =IF(COUNT($B36,J$34)<2,"",-U0*COS(PI()*J$34/L)*SIN(PI()*$B36/L)) -> -0.042096961 | K36: =IF(COUNT($B36,K$34)<2,"",-U0*COS(PI()*K$34/L)*SIN(PI()*$B36/L)) -> -0.032424172 | ... X36: =IF(COUNT($B36,X$34)<2,"",-U0*COS(PI()*X$34/L)*SIN(PI()*$B36/L)) -> 0.074521133
A37: 2 | B37: =IF(2<=N,(2-0.5)*dx,"") -> 0.071428571 | D37: =IF(COUNT($B37,D$34)<2,"",-U0*COS(PI()*D$34/L)*SIN(PI()*$B37/L)) -> -0.22189872 | E37: =IF(COUNT($B37,E$34)<2,"",-U0*COS(PI()*E$34/L)*SIN(PI()*$B37/L)) -> -0.21694187 | F37: =IF(COUNT($B37,F$34)<2,"",-U0*COS(PI()*F$34/L)*SIN(PI()*$B37/L)) -> -0.2071389 | G37: =IF(COUNT($B37,G$34)<2,"",-U0*COS(PI()*G$34/L)*SIN(PI()*$B37/L)) -> -0.19270878 | H37: =IF(COUNT($B37,H$34)<2,"",-U0*COS(PI()*H$34/L)*SIN(PI()*$B37/L)) -> -0.17397387 | I37: =IF(COUNT($B37,I$34)<2,"",-U0*COS(PI()*I$34/L)*SIN(PI()*$B37/L)) -> -0.15135267 | J37: =IF(COUNT($B37,J$34)<2,"",-U0*COS(PI()*J$34/L)*SIN(PI()*$B37/L)) -> -0.12535051 | K37: =IF(COUNT($B37,K$34)<2,"",-U0*COS(PI()*K$34/L)*SIN(PI()*$B37/L)) -> -0.096548215 | ... X37: =IF(COUNT($B37,X$34)<2,"",-U0*COS(PI()*X$34/L)*SIN(PI()*$B37/L)) -> 0.22189872
A38: 3 | B38: =IF(3<=N,(3-0.5)*dx,"") -> 0.11904762 | D38: =IF(COUNT($B38,D$34)<2,"",-U0*COS(PI()*D$34/L)*SIN(PI()*$B38/L)) -> -0.36431946 | E38: =IF(COUNT($B38,E$34)<2,"",-U0*COS(PI()*E$34/L)*SIN(PI()*$B38/L)) -> -0.35618116 | F38: =IF(COUNT($B38,F$34)<2,"",-U0*COS(PI()*F$34/L)*SIN(PI()*$B38/L)) -> -0.34008637 | G38: =IF(COUNT($B38,G$34)<2,"",-U0*COS(PI()*G$34/L)*SIN(PI()*$B38/L)) -> -0.31639461 | H38: =IF(COUNT($B38,H$34)<2,"",-U0*COS(PI()*H$34/L)*SIN(PI()*$B38/L)) -> -0.28563511 | I38: =IF(COUNT($B38,I$34)<2,"",-U0*COS(PI()*I$34/L)*SIN(PI()*$B38/L)) -> -0.248495 | J38: =IF(COUNT($B38,J$34)<2,"",-U0*COS(PI()*J$34/L)*SIN(PI()*$B38/L)) -> -0.20580393 | K38: =IF(COUNT($B38,K$34)<2,"",-U0*COS(PI()*K$34/L)*SIN(PI()*$B38/L)) -> -0.15851553 | ... X38: =IF(COUNT($B38,X$34)<2,"",-U0*COS(PI()*X$34/L)*SIN(PI()*$B38/L)) -> 0.36431946
A39: 4 | B39: =IF(4<=N,(4-0.5)*dx,"") -> 0.16666667 | D39: =IF(COUNT($B39,D$34)<2,"",-U0*COS(PI()*D$34/L)*SIN(PI()*$B39/L)) -> -0.4986019 | E39: =IF(COUNT($B39,E$34)<2,"",-U0*COS(PI()*E$34/L)*SIN(PI()*$B39/L)) -> -0.48746396 | F39: =IF(COUNT($B39,F$34)<2,"",-U0*COS(PI()*F$34/L)*SIN(PI()*$B39/L)) -> -0.46543687 | G39: =IF(COUNT($B39,G$34)<2,"",-U0*COS(PI()*G$34/L)*SIN(PI()*$B39/L)) -> -0.4330127 | H39: =IF(COUNT($B39,H$34)<2,"",-U0*COS(PI()*H$34/L)*SIN(PI()*$B39/L)) -> -0.39091574 | I39: =IF(COUNT($B39,I$34)<2,"",-U0*COS(PI()*I$34/L)*SIN(PI()*$B39/L)) -> -0.34008637 | J39: =IF(COUNT($B39,J$34)<2,"",-U0*COS(PI()*J$34/L)*SIN(PI()*$B39/L)) -> -0.28166003 | K39: =IF(COUNT($B39,K$34)<2,"",-U0*COS(PI()*K$34/L)*SIN(PI()*$B39/L)) -> -0.21694187 | ... X39: =IF(COUNT($B39,X$34)<2,"",-U0*COS(PI()*X$34/L)*SIN(PI()*$B39/L)) -> 0.4986019
A40: 5 | B40: =IF(5<=N,(5-0.5)*dx,"") -> 0.21428571 | D40: =IF(COUNT($B40,D$34)<2,"",-U0*COS(PI()*D$34/L)*SIN(PI()*$B40/L)) -> -0.6217464 | E40: =IF(COUNT($B40,E$34)<2,"",-U0*COS(PI()*E$34/L)*SIN(PI()*$B40/L)) -> -0.60785761 | F40: =IF(COUNT($B40,F$34)<2,"",-U0*COS(PI()*F$34/L)*SIN(PI()*$B40/L)) -> -0.58039029 | G40: =IF(COUNT($B40,G$34)<2,"",-U0*COS(PI()*G$34/L)*SIN(PI()*$B40/L)) -> -0.53995801 | H40: =IF(COUNT($B40,H$34)<2,"",-U0*COS(PI()*H$34/L)*SIN(PI()*$B40/L)) -> -0.48746396 | I40: =IF(COUNT($B40,I$34)<2,"",-U0*COS(PI()*I$34/L)*SIN(PI()*$B40/L)) -> -0.42408077 | J40: =IF(COUNT($B40,J$34)<2,"",-U0*COS(PI()*J$34/L)*SIN(PI()*$B40/L)) -> -0.35122431 | K40: =IF(COUNT($B40,K$34)<2,"",-U0*COS(PI()*K$34/L)*SIN(PI()*$B40/L)) -> -0.27052209 | ... X40: =IF(COUNT($B40,X$34)<2,"",-U0*COS(PI()*X$34/L)*SIN(PI()*$B40/L)) -> 0.6217464
A41: 6 | B41: =IF(6<=N,(6-0.5)*dx,"") -> 0.26190476 | D41: =IF(COUNT($B41,D$34)<2,"",-U0*COS(PI()*D$34/L)*SIN(PI()*$B41/L)) -> -0.73100211 | E41: =IF(COUNT($B41,E$34)<2,"",-U0*COS(PI()*E$34/L)*SIN(PI()*$B41/L)) -> -0.71467273 | F41: =IF(COUNT($B41,F$34)<2,"",-U0*COS(PI()*F$34/L)*SIN(PI()*$B41/L)) -> -0.68237874 | G41: =IF(COUNT($B41,G$34)<2,"",-U0*COS(PI()*G$34/L)*SIN(PI()*$B41/L)) -> -0.63484154 | H41: =IF(COUNT($B41,H$34)<2,"",-U0*COS(PI()*H$34/L)*SIN(PI()*$B41/L)) -> -0.57312303 | I41: =IF(COUNT($B41,I$34)<2,"",-U0*COS(PI()*I$34/L)*SIN(PI()*$B41/L)) -> -0.4986019 | J41: =IF(COUNT($B41,J$34)<2,"",-U0*COS(PI()*J$34/L)*SIN(PI()*$B41/L)) -> -0.41294282 | K41: =IF(COUNT($B41,K$34)<2,"",-U0*COS(PI()*K$34/L)*SIN(PI()*$B41/L)) -> -0.31805929 | ... X41: =IF(COUNT($B41,X$34)<2,"",-U0*COS(PI()*X$34/L)*SIN(PI()*$B41/L)) -> 0.73100211
A42: 7 | B42: =IF(7<=N,(7-0.5)*dx,"") -> 0.30952381 | D42: =IF(COUNT($B42,D$34)<2,"",-U0*COS(PI()*D$34/L)*SIN(PI()*$B42/L)) -> -0.82392844 | E42: =IF(COUNT($B42,E$34)<2,"",-U0*COS(PI()*E$34/L)*SIN(PI()*$B42/L)) -> -0.80552324 | F42: =IF(COUNT($B42,F$34)<2,"",-U0*COS(PI()*F$34/L)*SIN(PI()*$B42/L)) -> -0.76912399 | G42: =IF(COUNT($B42,G$34)<2,"",-U0*COS(PI()*G$34/L)*SIN(PI()*$B42/L)) -> -0.71554377 | H42: =IF(COUNT($B42,H$34)<2,"",-U0*COS(PI()*H$34/L)*SIN(PI()*$B42/L)) -> -0.64597949 | I42: =IF(COUNT($B42,I$34)<2,"",-U0*COS(PI()*I$34/L)*SIN(PI()*$B42/L)) -> -0.56198509 | J42: =IF(COUNT($B42,J$34)<2,"",-U0*COS(PI()*J$34/L)*SIN(PI()*$B42/L)) -> -0.46543687 | K42: =IF(COUNT($B42,K$34)<2,"",-U0*COS(PI()*K$34/L)*SIN(PI()*$B42/L)) -> -0.35849157 | ... X42: =IF(COUNT($B42,X$34)<2,"",-U0*COS(PI()*X$34/L)*SIN(PI()*$B42/L)) -> 0.82392844
A43: 8 | B43: =IF(8<=N,(8-0.5)*dx,"") -> 0.35714286 | D43: =IF(COUNT($B43,D$34)<2,"",-U0*COS(PI()*D$34/L)*SIN(PI()*$B43/L)) -> -0.89844958 | E43: =IF(COUNT($B43,E$34)<2,"",-U0*COS(PI()*E$34/L)*SIN(PI()*$B43/L)) -> -0.8783797 | F43: =IF(COUNT($B43,F$34)<2,"",-U0*COS(PI()*F$34/L)*SIN(PI()*$B43/L)) -> -0.83868827 | G43: =IF(COUNT($B43,G$34)<2,"",-U0*COS(PI()*G$34/L)*SIN(PI()*$B43/L)) -> -0.78026193 | H43: =IF(COUNT($B43,H$34)<2,"",-U0*COS(PI()*H$34/L)*SIN(PI()*$B43/L)) -> -0.70440583 | I43: =IF(COUNT($B43,I$34)<2,"",-U0*COS(PI()*I$34/L)*SIN(PI()*$B43/L)) -> -0.61281446 | J43: =IF(COUNT($B43,J$34)<2,"",-U0*COS(PI()*J$34/L)*SIN(PI()*$B43/L)) -> -0.50753383 | K43: =IF(COUNT($B43,K$34)<2,"",-U0*COS(PI()*K$34/L)*SIN(PI()*$B43/L)) -> -0.39091574 | ... X43: =IF(COUNT($B43,X$34)<2,"",-U0*COS(PI()*X$34/L)*SIN(PI()*$B43/L)) -> 0.89844958
A44: 9 | B44: =IF(9<=N,(9-0.5)*dx,"") -> 0.4047619 | D44: =IF(COUNT($B44,D$34)<2,"",-U0*COS(PI()*D$34/L)*SIN(PI()*$B44/L)) -> -0.95290083 | E44: =IF(COUNT($B44,E$34)<2,"",-U0*COS(PI()*E$34/L)*SIN(PI()*$B44/L)) -> -0.9316146 | F44: =IF(COUNT($B44,F$34)<2,"",-U0*COS(PI()*F$34/L)*SIN(PI()*$B44/L)) -> -0.88951764 | G44: =IF(COUNT($B44,G$34)<2,"",-U0*COS(PI()*G$34/L)*SIN(PI()*$B44/L)) -> -0.82755032 | H44: =IF(COUNT($B44,H$34)<2,"",-U0*COS(PI()*H$34/L)*SIN(PI()*$B44/L)) -> -0.7470969 | I44: =IF(COUNT($B44,I$34)<2,"",-U0*COS(PI()*I$34/L)*SIN(PI()*$B44/L)) -> -0.64995457 | J44: =IF(COUNT($B44,J$34)<2,"",-U0*COS(PI()*J$34/L)*SIN(PI()*$B44/L)) -> -0.53829333 | K44: =IF(COUNT($B44,K$34)<2,"",-U0*COS(PI()*K$34/L)*SIN(PI()*$B44/L)) -> -0.4146075 | ... X44: =IF(COUNT($B44,X$34)<2,"",-U0*COS(PI()*X$34/L)*SIN(PI()*$B44/L)) -> 0.95290083
...

Sheet Analytical
A1: F01 · Analytical
A2: The exact divergence of each field, equations (13) and (15).
A4: Exact divergence of field A, equation (13) [1/s]
A5: i | D5: 1 | E5: 2 | F5: 3 | G5: 4 | H5: 5 | I5: 6 | J5: 7 | K5: 8 | L5: 9 | M5: 10 | N5: 11 | O5: 12 | P5: 13 | Q5: 14 | R5: 15 | S5: 16 | T5: 17 | U5: 18 | V5: 19 | W5: 20 | X5: 21
A6: x [m] | D6: =IF(1<=N,(1-0.5)*dx,"") -> 0.023809524 | E6: =IF(2<=N,(2-0.5)*dx,"") -> 0.071428571 | F6: =IF(3<=N,(3-0.5)*dx,"") -> 0.11904762 | G6: =IF(4<=N,(4-0.5)*dx,"") -> 0.16666667 | H6: =IF(5<=N,(5-0.5)*dx,"") -> 0.21428571 | I6: =IF(6<=N,(6-0.5)*dx,"") -> 0.26190476 | J6: =IF(7<=N,(7-0.5)*dx,"") -> 0.30952381 | K6: =IF(8<=N,(8-0.5)*dx,"") -> 0.35714286 | L6: =IF(9<=N,(9-0.5)*dx,"") -> 0.4047619 | M6: =IF(10<=N,(10-0.5)*dx,"") -> 0.45238095 | N6: =IF(11<=N,(11-0.5)*dx,"") -> 0.5 | O6: =IF(12<=N,(12-0.5)*dx,"") -> 0.54761905 | P6: =IF(13<=N,(13-0.5)*dx,"") -> 0.5952381 | Q6: =IF(14<=N,(14-0.5)*dx,"") -> 0.64285714 | R6: =IF(15<=N,(15-0.5)*dx,"") -> 0.69047619 | S6: =IF(16<=N,(16-0.5)*dx,"") -> 0.73809524 | T6: =IF(17<=N,(17-0.5)*dx,"") -> 0.78571429 | U6: =IF(18<=N,(18-0.5)*dx,"") -> 0.83333333 | V6: =IF(19<=N,(19-0.5)*dx,"") -> 0.88095238 | W6: =IF(20<=N,(20-0.5)*dx,"") -> 0.92857143 | X6: =IF(21<=N,(21-0.5)*dx,"") -> 0.97619048
A7: j | B7: y [m]
A8: 1 | B8: =IF(1<=N,(1-0.5)*dx,"") -> 0.023809524 | D8: =IF(COUNT($B8,D$6)<2,"",0) -> 0 | E8: =IF(COUNT($B8,E$6)<2,"",0) -> 0 | F8: =IF(COUNT($B8,F$6)<2,"",0) -> 0 | G8: =IF(COUNT($B8,G$6)<2,"",0) -> 0 | H8: =IF(COUNT($B8,H$6)<2,"",0) -> 0 | I8: =IF(COUNT($B8,I$6)<2,"",0) -> 0 | J8: =IF(COUNT($B8,J$6)<2,"",0) -> 0 | K8: =IF(COUNT($B8,K$6)<2,"",0) -> 0 | ... X8: =IF(COUNT($B8,X$6)<2,"",0) -> 0
A9: 2 | B9: =IF(2<=N,(2-0.5)*dx,"") -> 0.071428571 | D9: =IF(COUNT($B9,D$6)<2,"",0) -> 0 | E9: =IF(COUNT($B9,E$6)<2,"",0) -> 0 | F9: =IF(COUNT($B9,F$6)<2,"",0) -> 0 | G9: =IF(COUNT($B9,G$6)<2,"",0) -> 0 | H9: =IF(COUNT($B9,H$6)<2,"",0) -> 0 | I9: =IF(COUNT($B9,I$6)<2,"",0) -> 0 | J9: =IF(COUNT($B9,J$6)<2,"",0) -> 0 | K9: =IF(COUNT($B9,K$6)<2,"",0) -> 0 | ... X9: =IF(COUNT($B9,X$6)<2,"",0) -> 0
A10: 3 | B10: =IF(3<=N,(3-0.5)*dx,"") -> 0.11904762 | D10: =IF(COUNT($B10,D$6)<2,"",0) -> 0 | E10: =IF(COUNT($B10,E$6)<2,"",0) -> 0 | F10: =IF(COUNT($B10,F$6)<2,"",0) -> 0 | G10: =IF(COUNT($B10,G$6)<2,"",0) -> 0 | H10: =IF(COUNT($B10,H$6)<2,"",0) -> 0 | I10: =IF(COUNT($B10,I$6)<2,"",0) -> 0 | J10: =IF(COUNT($B10,J$6)<2,"",0) -> 0 | K10: =IF(COUNT($B10,K$6)<2,"",0) -> 0 | ... X10: =IF(COUNT($B10,X$6)<2,"",0) -> 0
A11: 4 | B11: =IF(4<=N,(4-0.5)*dx,"") -> 0.16666667 | D11: =IF(COUNT($B11,D$6)<2,"",0) -> 0 | E11: =IF(COUNT($B11,E$6)<2,"",0) -> 0 | F11: =IF(COUNT($B11,F$6)<2,"",0) -> 0 | G11: =IF(COUNT($B11,G$6)<2,"",0) -> 0 | H11: =IF(COUNT($B11,H$6)<2,"",0) -> 0 | I11: =IF(COUNT($B11,I$6)<2,"",0) -> 0 | J11: =IF(COUNT($B11,J$6)<2,"",0) -> 0 | K11: =IF(COUNT($B11,K$6)<2,"",0) -> 0 | ... X11: =IF(COUNT($B11,X$6)<2,"",0) -> 0
A12: 5 | B12: =IF(5<=N,(5-0.5)*dx,"") -> 0.21428571 | D12: =IF(COUNT($B12,D$6)<2,"",0) -> 0 | E12: =IF(COUNT($B12,E$6)<2,"",0) -> 0 | F12: =IF(COUNT($B12,F$6)<2,"",0) -> 0 | G12: =IF(COUNT($B12,G$6)<2,"",0) -> 0 | H12: =IF(COUNT($B12,H$6)<2,"",0) -> 0 | I12: =IF(COUNT($B12,I$6)<2,"",0) -> 0 | J12: =IF(COUNT($B12,J$6)<2,"",0) -> 0 | K12: =IF(COUNT($B12,K$6)<2,"",0) -> 0 | ... X12: =IF(COUNT($B12,X$6)<2,"",0) -> 0
A13: 6 | B13: =IF(6<=N,(6-0.5)*dx,"") -> 0.26190476 | D13: =IF(COUNT($B13,D$6)<2,"",0) -> 0 | E13: =IF(COUNT($B13,E$6)<2,"",0) -> 0 | F13: =IF(COUNT($B13,F$6)<2,"",0) -> 0 | G13: =IF(COUNT($B13,G$6)<2,"",0) -> 0 | H13: =IF(COUNT($B13,H$6)<2,"",0) -> 0 | I13: =IF(COUNT($B13,I$6)<2,"",0) -> 0 | J13: =IF(COUNT($B13,J$6)<2,"",0) -> 0 | K13: =IF(COUNT($B13,K$6)<2,"",0) -> 0 | ... X13: =IF(COUNT($B13,X$6)<2,"",0) -> 0
A14: 7 | B14: =IF(7<=N,(7-0.5)*dx,"") -> 0.30952381 | D14: =IF(COUNT($B14,D$6)<2,"",0) -> 0 | E14: =IF(COUNT($B14,E$6)<2,"",0) -> 0 | F14: =IF(COUNT($B14,F$6)<2,"",0) -> 0 | G14: =IF(COUNT($B14,G$6)<2,"",0) -> 0 | H14: =IF(COUNT($B14,H$6)<2,"",0) -> 0 | I14: =IF(COUNT($B14,I$6)<2,"",0) -> 0 | J14: =IF(COUNT($B14,J$6)<2,"",0) -> 0 | K14: =IF(COUNT($B14,K$6)<2,"",0) -> 0 | ... X14: =IF(COUNT($B14,X$6)<2,"",0) -> 0
A15: 8 | B15: =IF(8<=N,(8-0.5)*dx,"") -> 0.35714286 | D15: =IF(COUNT($B15,D$6)<2,"",0) -> 0 | E15: =IF(COUNT($B15,E$6)<2,"",0) -> 0 | F15: =IF(COUNT($B15,F$6)<2,"",0) -> 0 | G15: =IF(COUNT($B15,G$6)<2,"",0) -> 0 | H15: =IF(COUNT($B15,H$6)<2,"",0) -> 0 | I15: =IF(COUNT($B15,I$6)<2,"",0) -> 0 | J15: =IF(COUNT($B15,J$6)<2,"",0) -> 0 | K15: =IF(COUNT($B15,K$6)<2,"",0) -> 0 | ... X15: =IF(COUNT($B15,X$6)<2,"",0) -> 0
A16: 9 | B16: =IF(9<=N,(9-0.5)*dx,"") -> 0.4047619 | D16: =IF(COUNT($B16,D$6)<2,"",0) -> 0 | E16: =IF(COUNT($B16,E$6)<2,"",0) -> 0 | F16: =IF(COUNT($B16,F$6)<2,"",0) -> 0 | G16: =IF(COUNT($B16,G$6)<2,"",0) -> 0 | H16: =IF(COUNT($B16,H$6)<2,"",0) -> 0 | I16: =IF(COUNT($B16,I$6)<2,"",0) -> 0 | J16: =IF(COUNT($B16,J$6)<2,"",0) -> 0 | K16: =IF(COUNT($B16,K$6)<2,"",0) -> 0 | ... X16: =IF(COUNT($B16,X$6)<2,"",0) -> 0
A17: 10 | B17: =IF(10<=N,(10-0.5)*dx,"") -> 0.45238095 | D17: =IF(COUNT($B17,D$6)<2,"",0) -> 0 | E17: =IF(COUNT($B17,E$6)<2,"",0) -> 0 | F17: =IF(COUNT($B17,F$6)<2,"",0) -> 0 | G17: =IF(COUNT($B17,G$6)<2,"",0) -> 0 | H17: =IF(COUNT($B17,H$6)<2,"",0) -> 0 | I17: =IF(COUNT($B17,I$6)<2,"",0) -> 0 | J17: =IF(COUNT($B17,J$6)<2,"",0) -> 0 | K17: =IF(COUNT($B17,K$6)<2,"",0) -> 0 | ... X17: =IF(COUNT($B17,X$6)<2,"",0) -> 0
A18: 11 | B18: =IF(11<=N,(11-0.5)*dx,"") -> 0.5 | D18: =IF(COUNT($B18,D$6)<2,"",0) -> 0 | E18: =IF(COUNT($B18,E$6)<2,"",0) -> 0 | F18: =IF(COUNT($B18,F$6)<2,"",0) -> 0 | G18: =IF(COUNT($B18,G$6)<2,"",0) -> 0 | H18: =IF(COUNT($B18,H$6)<2,"",0) -> 0 | I18: =IF(COUNT($B18,I$6)<2,"",0) -> 0 | J18: =IF(COUNT($B18,J$6)<2,"",0) -> 0 | K18: =IF(COUNT($B18,K$6)<2,"",0) -> 0 | ... X18: =IF(COUNT($B18,X$6)<2,"",0) -> 0
A19: 12 | B19: =IF(12<=N,(12-0.5)*dx,"") -> 0.54761905 | D19: =IF(COUNT($B19,D$6)<2,"",0) -> 0 | E19: =IF(COUNT($B19,E$6)<2,"",0) -> 0 | F19: =IF(COUNT($B19,F$6)<2,"",0) -> 0 | G19: =IF(COUNT($B19,G$6)<2,"",0) -> 0 | H19: =IF(COUNT($B19,H$6)<2,"",0) -> 0 | I19: =IF(COUNT($B19,I$6)<2,"",0) -> 0 | J19: =IF(COUNT($B19,J$6)<2,"",0) -> 0 | K19: =IF(COUNT($B19,K$6)<2,"",0) -> 0 | ... X19: =IF(COUNT($B19,X$6)<2,"",0) -> 0
A20: 13 | B20: =IF(13<=N,(13-0.5)*dx,"") -> 0.5952381 | D20: =IF(COUNT($B20,D$6)<2,"",0) -> 0 | E20: =IF(COUNT($B20,E$6)<2,"",0) -> 0 | F20: =IF(COUNT($B20,F$6)<2,"",0) -> 0 | G20: =IF(COUNT($B20,G$6)<2,"",0) -> 0 | H20: =IF(COUNT($B20,H$6)<2,"",0) -> 0 | I20: =IF(COUNT($B20,I$6)<2,"",0) -> 0 | J20: =IF(COUNT($B20,J$6)<2,"",0) -> 0 | K20: =IF(COUNT($B20,K$6)<2,"",0) -> 0 | ... X20: =IF(COUNT($B20,X$6)<2,"",0) -> 0
A21: 14 | B21: =IF(14<=N,(14-0.5)*dx,"") -> 0.64285714 | D21: =IF(COUNT($B21,D$6)<2,"",0) -> 0 | E21: =IF(COUNT($B21,E$6)<2,"",0) -> 0 | F21: =IF(COUNT($B21,F$6)<2,"",0) -> 0 | G21: =IF(COUNT($B21,G$6)<2,"",0) -> 0 | H21: =IF(COUNT($B21,H$6)<2,"",0) -> 0 | I21: =IF(COUNT($B21,I$6)<2,"",0) -> 0 | J21: =IF(COUNT($B21,J$6)<2,"",0) -> 0 | K21: =IF(COUNT($B21,K$6)<2,"",0) -> 0 | ... X21: =IF(COUNT($B21,X$6)<2,"",0) -> 0
A22: 15 | B22: =IF(15<=N,(15-0.5)*dx,"") -> 0.69047619 | D22: =IF(COUNT($B22,D$6)<2,"",0) -> 0 | E22: =IF(COUNT($B22,E$6)<2,"",0) -> 0 | F22: =IF(COUNT($B22,F$6)<2,"",0) -> 0 | G22: =IF(COUNT($B22,G$6)<2,"",0) -> 0 | H22: =IF(COUNT($B22,H$6)<2,"",0) -> 0 | I22: =IF(COUNT($B22,I$6)<2,"",0) -> 0 | J22: =IF(COUNT($B22,J$6)<2,"",0) -> 0 | K22: =IF(COUNT($B22,K$6)<2,"",0) -> 0 | ... X22: =IF(COUNT($B22,X$6)<2,"",0) -> 0
A23: 16 | B23: =IF(16<=N,(16-0.5)*dx,"") -> 0.73809524 | D23: =IF(COUNT($B23,D$6)<2,"",0) -> 0 | E23: =IF(COUNT($B23,E$6)<2,"",0) -> 0 | F23: =IF(COUNT($B23,F$6)<2,"",0) -> 0 | G23: =IF(COUNT($B23,G$6)<2,"",0) -> 0 | H23: =IF(COUNT($B23,H$6)<2,"",0) -> 0 | I23: =IF(COUNT($B23,I$6)<2,"",0) -> 0 | J23: =IF(COUNT($B23,J$6)<2,"",0) -> 0 | K23: =IF(COUNT($B23,K$6)<2,"",0) -> 0 | ... X23: =IF(COUNT($B23,X$6)<2,"",0) -> 0
A24: 17 | B24: =IF(17<=N,(17-0.5)*dx,"") -> 0.78571429 | D24: =IF(COUNT($B24,D$6)<2,"",0) -> 0 | E24: =IF(COUNT($B24,E$6)<2,"",0) -> 0 | F24: =IF(COUNT($B24,F$6)<2,"",0) -> 0 | G24: =IF(COUNT($B24,G$6)<2,"",0) -> 0 | H24: =IF(COUNT($B24,H$6)<2,"",0) -> 0 | I24: =IF(COUNT($B24,I$6)<2,"",0) -> 0 | J24: =IF(COUNT($B24,J$6)<2,"",0) -> 0 | K24: =IF(COUNT($B24,K$6)<2,"",0) -> 0 | ... X24: =IF(COUNT($B24,X$6)<2,"",0) -> 0
A25: 18 | B25: =IF(18<=N,(18-0.5)*dx,"") -> 0.83333333 | D25: =IF(COUNT($B25,D$6)<2,"",0) -> 0 | E25: =IF(COUNT($B25,E$6)<2,"",0) -> 0 | F25: =IF(COUNT($B25,F$6)<2,"",0) -> 0 | G25: =IF(COUNT($B25,G$6)<2,"",0) -> 0 | H25: =IF(COUNT($B25,H$6)<2,"",0) -> 0 | I25: =IF(COUNT($B25,I$6)<2,"",0) -> 0 | J25: =IF(COUNT($B25,J$6)<2,"",0) -> 0 | K25: =IF(COUNT($B25,K$6)<2,"",0) -> 0 | ... X25: =IF(COUNT($B25,X$6)<2,"",0) -> 0
A26: 19 | B26: =IF(19<=N,(19-0.5)*dx,"") -> 0.88095238 | D26: =IF(COUNT($B26,D$6)<2,"",0) -> 0 | E26: =IF(COUNT($B26,E$6)<2,"",0) -> 0 | F26: =IF(COUNT($B26,F$6)<2,"",0) -> 0 | G26: =IF(COUNT($B26,G$6)<2,"",0) -> 0 | H26: =IF(COUNT($B26,H$6)<2,"",0) -> 0 | I26: =IF(COUNT($B26,I$6)<2,"",0) -> 0 | J26: =IF(COUNT($B26,J$6)<2,"",0) -> 0 | K26: =IF(COUNT($B26,K$6)<2,"",0) -> 0 | ... X26: =IF(COUNT($B26,X$6)<2,"",0) -> 0
A27: 20 | B27: =IF(20<=N,(20-0.5)*dx,"") -> 0.92857143 | D27: =IF(COUNT($B27,D$6)<2,"",0) -> 0 | E27: =IF(COUNT($B27,E$6)<2,"",0) -> 0 | F27: =IF(COUNT($B27,F$6)<2,"",0) -> 0 | G27: =IF(COUNT($B27,G$6)<2,"",0) -> 0 | H27: =IF(COUNT($B27,H$6)<2,"",0) -> 0 | I27: =IF(COUNT($B27,I$6)<2,"",0) -> 0 | J27: =IF(COUNT($B27,J$6)<2,"",0) -> 0 | K27: =IF(COUNT($B27,K$6)<2,"",0) -> 0 | ... X27: =IF(COUNT($B27,X$6)<2,"",0) -> 0
A28: 21 | B28: =IF(21<=N,(21-0.5)*dx,"") -> 0.97619048 | D28: =IF(COUNT($B28,D$6)<2,"",0) -> 0 | E28: =IF(COUNT($B28,E$6)<2,"",0) -> 0 | F28: =IF(COUNT($B28,F$6)<2,"",0) -> 0 | G28: =IF(COUNT($B28,G$6)<2,"",0) -> 0 | H28: =IF(COUNT($B28,H$6)<2,"",0) -> 0 | I28: =IF(COUNT($B28,I$6)<2,"",0) -> 0 | J28: =IF(COUNT($B28,J$6)<2,"",0) -> 0 | K28: =IF(COUNT($B28,K$6)<2,"",0) -> 0 | ... X28: =IF(COUNT($B28,X$6)<2,"",0) -> 0
A32: Exact divergence of field B, equation (15) [1/s]
A33: i | D33: 1 | E33: 2 | F33: 3 | G33: 4 | H33: 5 | I33: 6 | J33: 7 | K33: 8 | L33: 9 | M33: 10 | N33: 11 | O33: 12 | P33: 13 | Q33: 14 | R33: 15 | S33: 16 | T33: 17 | U33: 18 | V33: 19 | W33: 20 | X33: 21
A34: x [m] | D34: =IF(1<=N,(1-0.5)*dx,"") -> 0.023809524 | E34: =IF(2<=N,(2-0.5)*dx,"") -> 0.071428571 | F34: =IF(3<=N,(3-0.5)*dx,"") -> 0.11904762 | G34: =IF(4<=N,(4-0.5)*dx,"") -> 0.16666667 | H34: =IF(5<=N,(5-0.5)*dx,"") -> 0.21428571 | I34: =IF(6<=N,(6-0.5)*dx,"") -> 0.26190476 | J34: =IF(7<=N,(7-0.5)*dx,"") -> 0.30952381 | K34: =IF(8<=N,(8-0.5)*dx,"") -> 0.35714286 | L34: =IF(9<=N,(9-0.5)*dx,"") -> 0.4047619 | M34: =IF(10<=N,(10-0.5)*dx,"") -> 0.45238095 | N34: =IF(11<=N,(11-0.5)*dx,"") -> 0.5 | O34: =IF(12<=N,(12-0.5)*dx,"") -> 0.54761905 | P34: =IF(13<=N,(13-0.5)*dx,"") -> 0.5952381 | Q34: =IF(14<=N,(14-0.5)*dx,"") -> 0.64285714 | R34: =IF(15<=N,(15-0.5)*dx,"") -> 0.69047619 | S34: =IF(16<=N,(16-0.5)*dx,"") -> 0.73809524 | T34: =IF(17<=N,(17-0.5)*dx,"") -> 0.78571429 | U34: =IF(18<=N,(18-0.5)*dx,"") -> 0.83333333 | V34: =IF(19<=N,(19-0.5)*dx,"") -> 0.88095238 | W34: =IF(20<=N,(20-0.5)*dx,"") -> 0.92857143 | X34: =IF(21<=N,(21-0.5)*dx,"") -> 0.97619048
A35: j | B35: y [m]
A36: 1 | B36: =IF(1<=N,(1-0.5)*dx,"") -> 0.023809524 | D36: =IF(COUNT($B36,D$34)<2,"",(PI()*U0/L)*COS(PI()*D$34/L)*SIN(PI()*$B36/L)) -> 0.23411504 | E36: =IF(COUNT($B36,E$34)<2,"",(PI()*U0/L)*COS(PI()*E$34/L)*SIN(PI()*$B36/L)) -> 0.2288853 | F36: =IF(COUNT($B36,F$34)<2,"",(PI()*U0/L)*COS(PI()*F$34/L)*SIN(PI()*$B36/L)) -> 0.21854264 | G36: =IF(COUNT($B36,G$34)<2,"",(PI()*U0/L)*COS(PI()*G$34/L)*SIN(PI()*$B36/L)) -> 0.20331809 | H36: =IF(COUNT($B36,H$34)<2,"",(PI()*U0/L)*COS(PI()*H$34/L)*SIN(PI()*$B36/L)) -> 0.18355176 | I36: =IF(COUNT($B36,I$34)<2,"",(PI()*U0/L)*COS(PI()*I$34/L)*SIN(PI()*$B36/L)) -> 0.15968518 | J36: =IF(COUNT($B36,J$34)<2,"",(PI()*U0/L)*COS(PI()*J$34/L)*SIN(PI()*$B36/L)) -> 0.1322515 | K36: =IF(COUNT($B36,K$34)<2,"",(PI()*U0/L)*COS(PI()*K$34/L)*SIN(PI()*$B36/L)) -> 0.10186354 | ... X36: =IF(COUNT($B36,X$34)<2,"",(PI()*U0/L)*COS(PI()*X$34/L)*SIN(PI()*$B36/L)) -> -0.23411504
A37: 2 | B37: =IF(2<=N,(2-0.5)*dx,"") -> 0.071428571 | D37: =IF(COUNT($B37,D$34)<2,"",(PI()*U0/L)*COS(PI()*D$34/L)*SIN(PI()*$B37/L)) -> 0.69711539 | E37: =IF(COUNT($B37,E$34)<2,"",(PI()*U0/L)*COS(PI()*E$34/L)*SIN(PI()*$B37/L)) -> 0.68154298 | F37: =IF(COUNT($B37,F$34)<2,"",(PI()*U0/L)*COS(PI()*F$34/L)*SIN(PI()*$B37/L)) -> 0.65074603 | G37: =IF(COUNT($B37,G$34)<2,"",(PI()*U0/L)*COS(PI()*G$34/L)*SIN(PI()*$B37/L)) -> 0.60541249 | H37: =IF(COUNT($B37,H$34)<2,"",(PI()*U0/L)*COS(PI()*H$34/L)*SIN(PI()*$B37/L)) -> 0.54655504 | I37: =IF(COUNT($B37,I$34)<2,"",(PI()*U0/L)*COS(PI()*I$34/L)*SIN(PI()*$B37/L)) -> 0.47548845 | J37: =IF(COUNT($B37,J$34)<2,"",(PI()*U0/L)*COS(PI()*J$34/L)*SIN(PI()*$B37/L)) -> 0.39380023 | K37: =IF(COUNT($B37,K$34)<2,"",(PI()*U0/L)*COS(PI()*K$34/L)*SIN(PI()*$B37/L)) -> 0.30331516 | ... X37: =IF(COUNT($B37,X$34)<2,"",(PI()*U0/L)*COS(PI()*X$34/L)*SIN(PI()*$B37/L)) -> -0.69711539
A38: 3 | B38: =IF(3<=N,(3-0.5)*dx,"") -> 0.11904762 | D38: =IF(COUNT($B38,D$34)<2,"",(PI()*U0/L)*COS(PI()*D$34/L)*SIN(PI()*$B38/L)) -> 1.1445433 | E38: =IF(COUNT($B38,E$34)<2,"",(PI()*U0/L)*COS(PI()*E$34/L)*SIN(PI()*$B38/L)) -> 1.1189761 | F38: =IF(COUNT($B38,F$34)<2,"",(PI()*U0/L)*COS(PI()*F$34/L)*SIN(PI()*$B38/L)) -> 1.0684128 | G38: =IF(COUNT($B38,G$34)<2,"",(PI()*U0/L)*COS(PI()*G$34/L)*SIN(PI()*$B38/L)) -> 0.99398298 | H38: =IF(COUNT($B38,H$34)<2,"",(PI()*U0/L)*COS(PI()*H$34/L)*SIN(PI()*$B38/L)) -> 0.89734918 | I38: =IF(COUNT($B38,I$34)<2,"",(PI()*U0/L)*COS(PI()*I$34/L)*SIN(PI()*$B38/L)) -> 0.78067008 | J38: =IF(COUNT($B38,J$34)<2,"",(PI()*U0/L)*COS(PI()*J$34/L)*SIN(PI()*$B38/L)) -> 0.64655211 | K38: =IF(COUNT($B38,K$34)<2,"",(PI()*U0/L)*COS(PI()*K$34/L)*SIN(PI()*$B38/L)) -> 0.49799122 | ... X38: =IF(COUNT($B38,X$34)<2,"",(PI()*U0/L)*COS(PI()*X$34/L)*SIN(PI()*$B38/L)) -> -1.1445433
A39: 4 | B39: =IF(4<=N,(4-0.5)*dx,"") -> 0.16666667 | D39: =IF(COUNT($B39,D$34)<2,"",(PI()*U0/L)*COS(PI()*D$34/L)*SIN(PI()*$B39/L)) -> 1.5664041 | E39: =IF(COUNT($B39,E$34)<2,"",(PI()*U0/L)*COS(PI()*E$34/L)*SIN(PI()*$B39/L)) -> 1.5314132 | F39: =IF(COUNT($B39,F$34)<2,"",(PI()*U0/L)*COS(PI()*F$34/L)*SIN(PI()*$B39/L)) -> 1.4622131 | G39: =IF(COUNT($B39,G$34)<2,"",(PI()*U0/L)*COS(PI()*G$34/L)*SIN(PI()*$B39/L)) -> 1.3603495 | H39: =IF(COUNT($B39,H$34)<2,"",(PI()*U0/L)*COS(PI()*H$34/L)*SIN(PI()*$B39/L)) -> 1.228098 | I39: =IF(COUNT($B39,I$34)<2,"",(PI()*U0/L)*COS(PI()*I$34/L)*SIN(PI()*$B39/L)) -> 1.0684128 | J39: =IF(COUNT($B39,J$34)<2,"",(PI()*U0/L)*COS(PI()*J$34/L)*SIN(PI()*$B39/L)) -> 0.88486108 | K39: =IF(COUNT($B39,K$34)<2,"",(PI()*U0/L)*COS(PI()*K$34/L)*SIN(PI()*$B39/L)) -> 0.68154298 | ... X39: =IF(COUNT($B39,X$34)<2,"",(PI()*U0/L)*COS(PI()*X$34/L)*SIN(PI()*$B39/L)) -> -1.5664041
A40: 5 | B40: =IF(5<=N,(5-0.5)*dx,"") -> 0.21428571 | D40: =IF(COUNT($B40,D$34)<2,"",(PI()*U0/L)*COS(PI()*D$34/L)*SIN(PI()*$B40/L)) -> 1.9532739 | E40: =IF(COUNT($B40,E$34)<2,"",(PI()*U0/L)*COS(PI()*E$34/L)*SIN(PI()*$B40/L)) -> 1.909641 | F40: =IF(COUNT($B40,F$34)<2,"",(PI()*U0/L)*COS(PI()*F$34/L)*SIN(PI()*$B40/L)) -> 1.8233499 | G40: =IF(COUNT($B40,G$34)<2,"",(PI()*U0/L)*COS(PI()*G$34/L)*SIN(PI()*$B40/L)) -> 1.6963281 | H40: =IF(COUNT($B40,H$34)<2,"",(PI()*U0/L)*COS(PI()*H$34/L)*SIN(PI()*$B40/L)) -> 1.5314132 | I40: =IF(COUNT($B40,I$34)<2,"",(PI()*U0/L)*COS(PI()*I$34/L)*SIN(PI()*$B40/L)) -> 1.332289 | J40: =IF(COUNT($B40,J$34)<2,"",(PI()*U0/L)*COS(PI()*J$34/L)*SIN(PI()*$B40/L)) -> 1.1034037 | K40: =IF(COUNT($B40,K$34)<2,"",(PI()*U0/L)*COS(PI()*K$34/L)*SIN(PI()*$B40/L)) -> 0.8498702 | ... X40: =IF(COUNT($B40,X$34)<2,"",(PI()*U0/L)*COS(PI()*X$34/L)*SIN(PI()*$B40/L)) -> -1.9532739
A41: 6 | B41: =IF(6<=N,(6-0.5)*dx,"") -> 0.26190476 | D41: =IF(COUNT($B41,D$34)<2,"",(PI()*U0/L)*COS(PI()*D$34/L)*SIN(PI()*$B41/L)) -> 2.2965109 | E41: =IF(COUNT($B41,E$34)<2,"",(PI()*U0/L)*COS(PI()*E$34/L)*SIN(PI()*$B41/L)) -> 2.2452106 | F41: =IF(COUNT($B41,F$34)<2,"",(PI()*U0/L)*COS(PI()*F$34/L)*SIN(PI()*$B41/L)) -> 2.143756 | G41: =IF(COUNT($B41,G$34)<2,"",(PI()*U0/L)*COS(PI()*G$34/L)*SIN(PI()*$B41/L)) -> 1.9944135 | H41: =IF(COUNT($B41,H$34)<2,"",(PI()*U0/L)*COS(PI()*H$34/L)*SIN(PI()*$B41/L)) -> 1.8005191 | I41: =IF(COUNT($B41,I$34)<2,"",(PI()*U0/L)*COS(PI()*I$34/L)*SIN(PI()*$B41/L)) -> 1.5664041 | J41: =IF(COUNT($B41,J$34)<2,"",(PI()*U0/L)*COS(PI()*J$34/L)*SIN(PI()*$B41/L)) -> 1.2972981 | K41: =IF(COUNT($B41,K$34)<2,"",(PI()*U0/L)*COS(PI()*K$34/L)*SIN(PI()*$B41/L)) -> 0.99921272 | ... X41: =IF(COUNT($B41,X$34)<2,"",(PI()*U0/L)*COS(PI()*X$34/L)*SIN(PI()*$B41/L)) -> -2.2965109
A42: 7 | B42: =IF(7<=N,(7-0.5)*dx,"") -> 0.30952381 | D42: =IF(COUNT($B42,D$34)<2,"",(PI()*U0/L)*COS(PI()*D$34/L)*SIN(PI()*$B42/L)) -> 2.5884475 | E42: =IF(COUNT($B42,E$34)<2,"",(PI()*U0/L)*COS(PI()*E$34/L)*SIN(PI()*$B42/L)) -> 2.5306259 | F42: =IF(COUNT($B42,F$34)<2,"",(PI()*U0/L)*COS(PI()*F$34/L)*SIN(PI()*$B42/L)) -> 2.4162743 | G42: =IF(COUNT($B42,G$34)<2,"",(PI()*U0/L)*COS(PI()*G$34/L)*SIN(PI()*$B42/L)) -> 2.247947 | H42: =IF(COUNT($B42,H$34)<2,"",(PI()*U0/L)*COS(PI()*H$34/L)*SIN(PI()*$B42/L)) -> 2.0294044 | I42: =IF(COUNT($B42,I$34)<2,"",(PI()*U0/L)*COS(PI()*I$34/L)*SIN(PI()*$B42/L)) -> 1.7655282 | J42: =IF(COUNT($B42,J$34)<2,"",(PI()*U0/L)*COS(PI()*J$34/L)*SIN(PI()*$B42/L)) -> 1.4622131 | K42: =IF(COUNT($B42,K$34)<2,"",(PI()*U0/L)*COS(PI()*K$34/L)*SIN(PI()*$B42/L)) -> 1.1262345 | ... X42: =IF(COUNT($B42,X$34)<2,"",(PI()*U0/L)*COS(PI()*X$34/L)*SIN(PI()*$B42/L)) -> -2.5884475
A43: 8 | B43: =IF(8<=N,(8-0.5)*dx,"") -> 0.35714286 | D43: =IF(COUNT($B43,D$34)<2,"",(PI()*U0/L)*COS(PI()*D$34/L)*SIN(PI()*$B43/L)) -> 2.8225626 | E43: =IF(COUNT($B43,E$34)<2,"",(PI()*U0/L)*COS(PI()*E$34/L)*SIN(PI()*$B43/L)) -> 2.7595112 | F43: =IF(COUNT($B43,F$34)<2,"",(PI()*U0/L)*COS(PI()*F$34/L)*SIN(PI()*$B43/L)) -> 2.6348169 | G43: =IF(COUNT($B43,G$34)<2,"",(PI()*U0/L)*COS(PI()*G$34/L)*SIN(PI()*$B43/L)) -> 2.4512651 | H43: =IF(COUNT($B43,H$34)<2,"",(PI()*U0/L)*COS(PI()*H$34/L)*SIN(PI()*$B43/L)) -> 2.2129562 | I43: =IF(COUNT($B43,I$34)<2,"",(PI()*U0/L)*COS(PI()*I$34/L)*SIN(PI()*$B43/L)) -> 1.9252134 | J43: =IF(COUNT($B43,J$34)<2,"",(PI()*U0/L)*COS(PI()*J$34/L)*SIN(PI()*$B43/L)) -> 1.5944646 | K43: =IF(COUNT($B43,K$34)<2,"",(PI()*U0/L)*COS(PI()*K$34/L)*SIN(PI()*$B43/L)) -> 1.228098 | ... X43: =IF(COUNT($B43,X$34)<2,"",(PI()*U0/L)*COS(PI()*X$34/L)*SIN(PI()*$B43/L)) -> -2.8225626
A44: 9 | B44: =IF(9<=N,(9-0.5)*dx,"") -> 0.4047619 | D44: =IF(COUNT($B44,D$34)<2,"",(PI()*U0/L)*COS(PI()*D$34/L)*SIN(PI()*$B44/L)) -> 2.9936262 | E44: =IF(COUNT($B44,E$34)<2,"",(PI()*U0/L)*COS(PI()*E$34/L)*SIN(PI()*$B44/L)) -> 2.9267536 | F44: =IF(COUNT($B44,F$34)<2,"",(PI()*U0/L)*COS(PI()*F$34/L)*SIN(PI()*$B44/L)) -> 2.7945021 | G44: =IF(COUNT($B44,G$34)<2,"",(PI()*U0/L)*COS(PI()*G$34/L)*SIN(PI()*$B44/L)) -> 2.599826 | H44: =IF(COUNT($B44,H$34)<2,"",(PI()*U0/L)*COS(PI()*H$34/L)*SIN(PI()*$B44/L)) -> 2.3470741 | I44: =IF(COUNT($B44,I$34)<2,"",(PI()*U0/L)*COS(PI()*I$34/L)*SIN(PI()*$B44/L)) -> 2.0418925 | J44: =IF(COUNT($B44,J$34)<2,"",(PI()*U0/L)*COS(PI()*J$34/L)*SIN(PI()*$B44/L)) -> 1.6910984 | K44: =IF(COUNT($B44,K$34)<2,"",(PI()*U0/L)*COS(PI()*K$34/L)*SIN(PI()*$B44/L)) -> 1.3025279 | ... X44: =IF(COUNT($B44,X$34)<2,"",(PI()*U0/L)*COS(PI()*X$34/L)*SIN(PI()*$B44/L)) -> -2.9936262
...

Sheet Error
A1: F01 · Error
A3: Error on the main grid
A4: Quantity | B4: Field A | C4: Field B | D4: Unit
A5: maximum error | B5: =MAX(errA) -> 2.4424907e-15 | C5: =MAX(errB) -> 0.011411594 | D5: 1/s
A6: RMS error | B6: =SQRT(SUMSQ(errA)/COUNT(errA)) -> 8.3710805e-16 | C6: =SQRT(SUMSQ(errB)/COUNT(errB)) -> 0.0058207419 | D6: 1/s
A7: interior nodes counted | B7: =COUNT(errA) -> 361 | C7: =COUNT(errB) -> 361
A9: Mass balance over the control volume
A10: Trapezoid rule on both sides, over the box given by ia, ib, ja, jb on the Inputs tab.
A11: Quantity | B11: Field A | C11: Field B | D11: Unit
A12: surface integral | B12: =rho*((dx*(SUM(INDEX(uA,ja,ib):INDEX(uA,jb,ib))-0.5*(INDEX(uA,ja,ib)+INDEX(uA,jb,ib))))-(dx*(SUM(INDEX(uA,ja,ia):INDEX(uA,jb,ia))-0.5*(INDEX(uA,ja,ia)+INDEX(uA,jb,ia))))+(dx*(SUM(INDEX(vA,jb,ia):INDEX(vA,jb,ib))-0.5*(INDEX(vA,jb,ia)+INDEX(vA,jb,ib))))-(dx*(SUM(INDEX(vA,ja,ia):INDEX(vA,ja,ib))-0.5*(INDEX(vA,ja,ia)+INDEX(vA,ja,ib))))) -> 1.3877788e-17 | C12: =rho*((dx*(SUM(INDEX(uB,ja,ib):INDEX(uB,jb,ib))-0.5*(INDEX(uB,ja,ib)+INDEX(uB,jb,ib))))-(dx*(SUM(INDEX(uB,ja,ia):INDEX(uB,jb,ia))-0.5*(INDEX(uB,ja,ia)+INDEX(uB,jb,ia))))+(dx*(SUM(INDEX(vB,jb,ia):INDEX(vB,jb,ib))-0.5*(INDEX(vB,jb,ia)+INDEX(vB,jb,ib))))-(dx*(SUM(INDEX(vB,ja,ia):INDEX(vB,ja,ib))-0.5*(INDEX(vB,ja,ia)+INDEX(vB,ja,ib))))) -> 0.2932276 | D12: kg/(m s)
A13: volume integral | B13: =rho*dx*dx*(SUM(INDEX(DA,ja,ia):INDEX(DA,jb,ib))-0.5*(SUM(INDEX(DA,ja,ia):INDEX(DA,ja,ib))+SUM(INDEX(DA,jb,ia):INDEX(DA,jb,ib))+SUM(INDEX(DA,ja,ia):INDEX(DA,jb,ia))+SUM(INDEX(DA,ja,ib):INDEX(DA,jb,ib)))+0.25*(INDEX(DA,ja,ia)+INDEX(DA,ja,ib)+INDEX(DA,jb,ia)+INDEX(DA,jb,ib))) -> -8.3264783e-18 | C13: =rho*dx*dx*(SUM(INDEX(DB,ja,ia):INDEX(DB,jb,ib))-0.5*(SUM(INDEX(DB,ja,ia):INDEX(DB,ja,ib))+SUM(INDEX(DB,jb,ia):INDEX(DB,jb,ib))+SUM(INDEX(DB,ja,ia):INDEX(DB,jb,ia))+SUM(INDEX(DB,ja,ib):INDEX(DB,jb,ib)))+0.25*(INDEX(DB,ja,ia)+INDEX(DB,ja,ib)+INDEX(DB,jb,ia)+INDEX(DB,jb,ib))) -> 0.29159005 | D13: kg/(m s)
A14: difference | B14: =ABS(B12-B13) -> 2.2204266e-17 | C14: =ABS(C12-C13) -> 0.001637555 | D14: kg/(m s)
A15: relative difference | B15: =IF(ABS(B13)<0.000000000001,"-",B14/ABS(B13)) -> - | C15: =IF(ABS(C13)<0.000000000001,"-",C14/ABS(C13)) -> 0.0056159496 | D15: -
A17: Grid study, field B
A18: Change N_3, N_2 and N on the Inputs tab to move the three grids.
A19: N | B19: dx [m] | C19: maximum error [1/s] | D19: RMS error [1/s] | E19: p from maximum | F19: p from RMS
A20: =N_3 -> 6 | B20: =dx_3 -> 0.16666667 | C20: =MAX(err_3) -> 0.096709581 | D20: =SQRT(SUMSQ(err_3)/COUNT(err_3)) -> 0.063814947
A21: =N_2 -> 11 | B21: =dx_2 -> 0.090909091 | C21: =MAX(err_2) -> 0.038690768 | D21: =SQRT(SUMSQ(err_2)/COUNT(err_2)) -> 0.020778204 | E21: =LN(C20/C21)/LN(B20/B21) -> 1.5113964 | F21: =LN(D20/D21)/LN(B20/B21) -> 1.8512071
A22: =N -> 21 | B22: =dx -> 0.047619048 | C22: =MAX(errB) -> 0.011411594 | D22: =SQRT(SUMSQ(errB)/COUNT(errB)) -> 0.0058207419 | E22: =LN(C21/C22)/LN(B21/B22) -> 1.8882151 | F22: =LN(D21/D22)/LN(B21/B22) -> 1.9678679
A24: The central difference of equation (10) is second order, so p approaches 2 as the grid is refined.
A45: Absolute error of field A, main grid [1/s]
A46: i | D46: 1 | E46: 2 | F46: 3 | G46: 4 | H46: 5 | I46: 6 | J46: 7 | K46: 8 | L46: 9 | M46: 10 | N46: 11 | O46: 12 | P46: 13 | Q46: 14 | R46: 15 | S46: 16 | T46: 17 | U46: 18 | V46: 19 | W46: 20 | X46: 21
A47: x [m] | D47: =IF(1<=N,(1-0.5)*dx,"") -> 0.023809524 | E47: =IF(2<=N,(2-0.5)*dx,"") -> 0.071428571 | F47: =IF(3<=N,(3-0.5)*dx,"") -> 0.11904762 | G47: =IF(4<=N,(4-0.5)*dx,"") -> 0.16666667 | H47: =IF(5<=N,(5-0.5)*dx,"") -> 0.21428571 | I47: =IF(6<=N,(6-0.5)*dx,"") -> 0.26190476 | J47: =IF(7<=N,(7-0.5)*dx,"") -> 0.30952381 | K47: =IF(8<=N,(8-0.5)*dx,"") -> 0.35714286 | L47: =IF(9<=N,(9-0.5)*dx,"") -> 0.4047619 | M47: =IF(10<=N,(10-0.5)*dx,"") -> 0.45238095 | N47: =IF(11<=N,(11-0.5)*dx,"") -> 0.5 | O47: =IF(12<=N,(12-0.5)*dx,"") -> 0.54761905 | P47: =IF(13<=N,(13-0.5)*dx,"") -> 0.5952381 | Q47: =IF(14<=N,(14-0.5)*dx,"") -> 0.64285714 | R47: =IF(15<=N,(15-0.5)*dx,"") -> 0.69047619 | S47: =IF(16<=N,(16-0.5)*dx,"") -> 0.73809524 | T47: =IF(17<=N,(17-0.5)*dx,"") -> 0.78571429 | U47: =IF(18<=N,(18-0.5)*dx,"") -> 0.83333333 | V47: =IF(19<=N,(19-0.5)*dx,"") -> 0.88095238 | W47: =IF(20<=N,(20-0.5)*dx,"") -> 0.92857143 | X47: =IF(21<=N,(21-0.5)*dx,"") -> 0.97619048
A48: j | B48: y [m]
A49: 1 | B49: =IF(1<=N,(1-0.5)*dx,"") -> 0.023809524 | D49: =IF(COUNT(Solver!D64)<1,"",ABS(Solver!D64-Analytical!D8)) | E49: =IF(COUNT(Solver!E64)<1,"",ABS(Solver!E64-Analytical!E8)) | F49: =IF(COUNT(Solver!F64)<1,"",ABS(Solver!F64-Analytical!F8)) | G49: =IF(COUNT(Solver!G64)<1,"",ABS(Solver!G64-Analytical!G8)) | H49: =IF(COUNT(Solver!H64)<1,"",ABS(Solver!H64-Analytical!H8)) | I49: =IF(COUNT(Solver!I64)<1,"",ABS(Solver!I64-Analytical!I8)) | J49: =IF(COUNT(Solver!J64)<1,"",ABS(Solver!J64-Analytical!J8)) | K49: =IF(COUNT(Solver!K64)<1,"",ABS(Solver!K64-Analytical!K8)) | ... X49: =IF(COUNT(Solver!X64)<1,"",ABS(Solver!X64-Analytical!X8))
A50: 2 | B50: =IF(2<=N,(2-0.5)*dx,"") -> 0.071428571 | D50: =IF(COUNT(Solver!D65)<1,"",ABS(Solver!D65-Analytical!D9)) | E50: =IF(COUNT(Solver!E65)<1,"",ABS(Solver!E65-Analytical!E9)) -> 0 | F50: =IF(COUNT(Solver!F65)<1,"",ABS(Solver!F65-Analytical!F9)) -> 0 | G50: =IF(COUNT(Solver!G65)<1,"",ABS(Solver!G65-Analytical!G9)) -> 4.4408921e-16 | H50: =IF(COUNT(Solver!H65)<1,"",ABS(Solver!H65-Analytical!H9)) -> 4.4408921e-16 | I50: =IF(COUNT(Solver!I65)<1,"",ABS(Solver!I65-Analytical!I9)) -> 4.4408921e-16 | J50: =IF(COUNT(Solver!J65)<1,"",ABS(Solver!J65-Analytical!J9)) -> 2.220446e-16 | K50: =IF(COUNT(Solver!K65)<1,"",ABS(Solver!K65-Analytical!K9)) -> 1.5543122e-15 | ... X50: =IF(COUNT(Solver!X65)<1,"",ABS(Solver!X65-Analytical!X9))
A51: 3 | B51: =IF(3<=N,(3-0.5)*dx,"") -> 0.11904762 | D51: =IF(COUNT(Solver!D66)<1,"",ABS(Solver!D66-Analytical!D10)) | E51: =IF(COUNT(Solver!E66)<1,"",ABS(Solver!E66-Analytical!E10)) -> 0 | F51: =IF(COUNT(Solver!F66)<1,"",ABS(Solver!F66-Analytical!F10)) -> 0 | G51: =IF(COUNT(Solver!G66)<1,"",ABS(Solver!G66-Analytical!G10)) -> 4.4408921e-16 | H51: =IF(COUNT(Solver!H66)<1,"",ABS(Solver!H66-Analytical!H10)) -> 4.4408921e-16 | I51: =IF(COUNT(Solver!I66)<1,"",ABS(Solver!I66-Analytical!I10)) -> 2.220446e-16 | J51: =IF(COUNT(Solver!J66)<1,"",ABS(Solver!J66-Analytical!J10)) -> 8.8817842e-16 | K51: =IF(COUNT(Solver!K66)<1,"",ABS(Solver!K66-Analytical!K10)) -> 6.6613381e-16 | ... X51: =IF(COUNT(Solver!X66)<1,"",ABS(Solver!X66-Analytical!X10))
A52: 4 | B52: =IF(4<=N,(4-0.5)*dx,"") -> 0.16666667 | D52: =IF(COUNT(Solver!D67)<1,"",ABS(Solver!D67-Analytical!D11)) | E52: =IF(COUNT(Solver!E67)<1,"",ABS(Solver!E67-Analytical!E11)) -> 4.4408921e-16 | F52: =IF(COUNT(Solver!F67)<1,"",ABS(Solver!F67-Analytical!F11)) -> 4.4408921e-16 | G52: =IF(COUNT(Solver!G67)<1,"",ABS(Solver!G67-Analytical!G11)) -> 0 | H52: =IF(COUNT(Solver!H67)<1,"",ABS(Solver!H67-Analytical!H11)) -> 0 | I52: =IF(COUNT(Solver!I67)<1,"",ABS(Solver!I67-Analytical!I11)) -> 2.220446e-16 | J52: =IF(COUNT(Solver!J67)<1,"",ABS(Solver!J67-Analytical!J11)) -> 8.8817842e-16 | K52: =IF(COUNT(Solver!K67)<1,"",ABS(Solver!K67-Analytical!K11)) -> 2.4424907e-15 | ... X52: =IF(COUNT(Solver!X67)<1,"",ABS(Solver!X67-Analytical!X11))
A53: 5 | B53: =IF(5<=N,(5-0.5)*dx,"") -> 0.21428571 | D53: =IF(COUNT(Solver!D68)<1,"",ABS(Solver!D68-Analytical!D12)) | E53: =IF(COUNT(Solver!E68)<1,"",ABS(Solver!E68-Analytical!E12)) -> 4.4408921e-16 | F53: =IF(COUNT(Solver!F68)<1,"",ABS(Solver!F68-Analytical!F12)) -> 4.4408921e-16 | G53: =IF(COUNT(Solver!G68)<1,"",ABS(Solver!G68-Analytical!G12)) -> 0 | H53: =IF(COUNT(Solver!H68)<1,"",ABS(Solver!H68-Analytical!H12)) -> 0 | I53: =IF(COUNT(Solver!I68)<1,"",ABS(Solver!I68-Analytical!I12)) -> 1.3322676e-15 | J53: =IF(COUNT(Solver!J68)<1,"",ABS(Solver!J68-Analytical!J12)) -> 6.6613381e-16 | K53: =IF(COUNT(Solver!K68)<1,"",ABS(Solver!K68-Analytical!K12)) -> 1.7763568e-15 | ... X53: =IF(COUNT(Solver!X68)<1,"",ABS(Solver!X68-Analytical!X12))
A54: 6 | B54: =IF(6<=N,(6-0.5)*dx,"") -> 0.26190476 | D54: =IF(COUNT(Solver!D69)<1,"",ABS(Solver!D69-Analytical!D13)) | E54: =IF(COUNT(Solver!E69)<1,"",ABS(Solver!E69-Analytical!E13)) -> 4.4408921e-16 | F54: =IF(COUNT(Solver!F69)<1,"",ABS(Solver!F69-Analytical!F13)) -> 2.220446e-16 | G54: =IF(COUNT(Solver!G69)<1,"",ABS(Solver!G69-Analytical!G13)) -> 2.220446e-16 | H54: =IF(COUNT(Solver!H69)<1,"",ABS(Solver!H69-Analytical!H13)) -> 1.3322676e-15 | I54: =IF(COUNT(Solver!I69)<1,"",ABS(Solver!I69-Analytical!I13)) -> 0 | J54: =IF(COUNT(Solver!J69)<1,"",ABS(Solver!J69-Analytical!J13)) -> 6.6613381e-16 | K54: =IF(COUNT(Solver!K69)<1,"",ABS(Solver!K69-Analytical!K13)) -> 1.110223e-15 | ... X54: =IF(COUNT(Solver!X69)<1,"",ABS(Solver!X69-Analytical!X13))
A55: 7 | B55: =IF(7<=N,(7-0.5)*dx,"") -> 0.30952381 | D55: =IF(COUNT(Solver!D70)<1,"",ABS(Solver!D70-Analytical!D14)) | E55: =IF(COUNT(Solver!E70)<1,"",ABS(Solver!E70-Analytical!E14)) -> 2.220446e-16 | F55: =IF(COUNT(Solver!F70)<1,"",ABS(Solver!F70-Analytical!F14)) -> 8.8817842e-16 | G55: =IF(COUNT(Solver!G70)<1,"",ABS(Solver!G70-Analytical!G14)) -> 8.8817842e-16 | H55: =IF(COUNT(Solver!H70)<1,"",ABS(Solver!H70-Analytical!H14)) -> 6.6613381e-16 | I55: =IF(COUNT(Solver!I70)<1,"",ABS(Solver!I70-Analytical!I14)) -> 6.6613381e-16 | J55: =IF(COUNT(Solver!J70)<1,"",ABS(Solver!J70-Analytical!J14)) -> 0 | K55: =IF(COUNT(Solver!K70)<1,"",ABS(Solver!K70-Analytical!K14)) -> 1.2212453e-15 | ... X55: =IF(COUNT(Solver!X70)<1,"",ABS(Solver!X70-Analytical!X14))
A56: 8 | B56: =IF(8<=N,(8-0.5)*dx,"") -> 0.35714286 | D56: =IF(COUNT(Solver!D71)<1,"",ABS(Solver!D71-Analytical!D15)) | E56: =IF(COUNT(Solver!E71)<1,"",ABS(Solver!E71-Analytical!E15)) -> 1.5543122e-15 | F56: =IF(COUNT(Solver!F71)<1,"",ABS(Solver!F71-Analytical!F15)) -> 6.6613381e-16 | G56: =IF(COUNT(Solver!G71)<1,"",ABS(Solver!G71-Analytical!G15)) -> 2.4424907e-15 | H56: =IF(COUNT(Solver!H71)<1,"",ABS(Solver!H71-Analytical!H15)) -> 1.7763568e-15 | I56: =IF(COUNT(Solver!I71)<1,"",ABS(Solver!I71-Analytical!I15)) -> 1.110223e-15 | J56: =IF(COUNT(Solver!J71)<1,"",ABS(Solver!J71-Analytical!J15)) -> 1.2212453e-15 | K56: =IF(COUNT(Solver!K71)<1,"",ABS(Solver!K71-Analytical!K15)) -> 0 | ... X56: =IF(COUNT(Solver!X71)<1,"",ABS(Solver!X71-Analytical!X15))
A57: 9 | B57: =IF(9<=N,(9-0.5)*dx,"") -> 0.4047619 | D57: =IF(COUNT(Solver!D72)<1,"",ABS(Solver!D72-Analytical!D16)) | E57: =IF(COUNT(Solver!E72)<1,"",ABS(Solver!E72-Analytical!E16)) -> 1.2212453e-15 | F57: =IF(COUNT(Solver!F72)<1,"",ABS(Solver!F72-Analytical!F16)) -> 5.5511151e-16 | G57: =IF(COUNT(Solver!G72)<1,"",ABS(Solver!G72-Analytical!G16)) -> 1.110223e-16 | H57: =IF(COUNT(Solver!H72)<1,"",ABS(Solver!H72-Analytical!H16)) -> 5.5511151e-16 | I57: =IF(COUNT(Solver!I72)<1,"",ABS(Solver!I72-Analytical!I16)) -> 2.220446e-16 | J57: =IF(COUNT(Solver!J72)<1,"",ABS(Solver!J72-Analytical!J16)) -> 0 | K57: =IF(COUNT(Solver!K72)<1,"",ABS(Solver!K72-Analytical!K16)) -> 5.5511151e-16 | ... X57: =IF(COUNT(Solver!X72)<1,"",ABS(Solver!X72-Analytical!X16))
